Workbook

Sheet LIQ
A1: MIS EXPENSAS- Liquidación de | G1: MES: | H1: 46143
A2: ADMINISTRACION: | G2: CONSORCIO DE PROPIETARIOS:
A3: MARIANO CAUVIN | G3: LIMA 461/67/73 C.A.B.A.
A4: AV.BELGRANO 1270 5°A C.A.B.A. | G4: CUIT: 30-53267348-4
A5: masoca_administraciones@hotmail.com | F5: 4381-0014 | G5: CLAVE SUTERH: 5073
A6: 20-16975070-0 | F6: Responsable Monotributo
A7: R.P.A. N° 470 | F7: URGENCIAS 155248-3729
B9: PAGOS DEL PERIODO | G9: GASTOS "A" y "B" | H9: TOTAL | I9: %
B10: REMUNERACIONES AL PERSONAL Y CARGAS SOCIALES | K10: EFECTIVO | L10: BANCO | M10: A DEBITAR | N10: TOTAL
B11: Conf. Art. 10 inc.d Ley N°941
A12: 1 | B12: DETALLE DE SUELDOS Y CARGAS SOCIALES: | H12: =SUM(G13:G29) -> 1444814.7 | I12: =+H12/H72 -> 0.46836554 | K12: 0 | L12: =+G24+G25+G26+G27+G28+G29 -> 656057.69 | M12: =+G14 -> 788757 | N12: =SUM(K12:M12) -> 1444814.7
B13: Encargado no permanente sin vivienda 3°categoría:
B14: Giacomo Sebastian (20-36064777-4): sueldo neto 05/26 | G14: 788757
B15: Sueldo básico | E15: 598586
B16: Plus por Antigüedad- 12 años | E16: 252139.2
B17: Retiro de residuos | E17: 15527.2
B18: Clasif.de residuos Res 243/13 SSRT CABA | E18: 33429.7
B19: Adicional viáticos | E19: 73765.1
B20: Adicional remuneratorio | E20: 40000
B21: Total bruto | E21: =SUM(E15:E20) -> 1013447.2
B22: Dtos legales | E22: -224690.52
B23: Sueldo neto | E23: =SUM(E21:E22) -> 788756.68
B24: ARCA AFIP F 931: Cargas sociales: SIJP y Obra social 04/26 | G24: 410153.67
B25: ARCA AFIP 931 : ART 04/26 | G25: 111523.28
B26: ARCA AFIP 931: Seguro colectivo de vida obligatorio SCVO 04/26 | G26: 424.62
B27: SUTERH 04/26 | G27: 43958.79
B28: FATERYH 04/26 | G28: 85113.02
B29: FATERYH-SERACARH 04/26 | G29: 4884.31
B31: PAGOS POR SUMINISTROS, SERVICIOS, ABONOS Y SEGUROS
B32: Conf. Art. 10 inc. e y f Ley N°941
A33: 2 | B33: SERVICIOS PUBLICOS Y TASAS | H33: =SUM(G34:G36) -> 103423.53 | I33: =+H33/H72 -> 0.033526803 | K33: 0 | L33: =+G34+G36 -> 103423.53 | M33: 0 | N33: =SUM(K33:M33) -> 103423.53
B34: Edesur Edificio cliente 324471. Periodo 5. Débito 21/05 | G34: 98497.83
B35: Edesur Portería cliente 324475. Periodo 5. Vto. 29/05 | G35: 0
B36: Metrogas Medidor 16219365 28/02 al 31/03 liq. 1/2 | G36: 4925.7
A38: 3 | B38: ABONOS DE SERVICIOS | H38: =SUM(G39:G44) -> 446280 | I38: =+H38/H72 -> 0.14467058 | K38: 0 | L38: =+G39+G40+G43+G44 -> 366280 | M38: 0 | N38: =SUM(K38:M38) -> 366280
B39: EMEGA SRL (30-71582332-9): abono mantenimiento ascensor 04/26 FC 49247 | G39: 125000 | M39: ,
B40: MAFRAP (30-64714402-7): serv. de desinsectación 04/26 FC 180556 | G40: 81490
B41: MAFRAP (30-64714402-7): desratización, colocación de cebos, monitoreo y control 2 semanas
B42: FC 181104 | G42: 80000
B43: Machinandiarena (20-06144196-5): limpieza tanques de agua potable. Cuota 1/6 FC 1505 | G43: 70000
...

Sheet RES CUENTA
A3: =+LIQ!A2 -> ADMINISTRACION: | P3: =+LIQ!G2 -> CONSORCIO DE PROPIETARIOS: | X3: Gastos comunes f
A4: =+LIQ!A3 -> MARIANO CAUVIN | P4: =+LIQ!G3 -> LIMA 461/67/73 C.A.B.A. | X4: Cuidado reparación y gastos por ascensores quedando excluido por esta contribucion los locales de PB
A5: =+LIQ!A4 -> AV.BELGRANO 1270 5°A C.A.B.A. | P5: =+LIQ!G4 -> CUIT: 30-53267348-4
A6: =+LIQ!A5 -> masoca_administraciones@hotmail.com | G6: =+LIQ!F5 -> 4381-0014 | P6: =+LIQ!G5 -> CLAVE SUTERH: 5073
A7: =+LIQ!A6 -> 20-16975070-0 | G7: =+LIQ!F6 -> Responsable Monotributo
A8: =+LIQ!A7 -> R.P.A. N° 470 | G8: =+LIQ!F7 -> URGENCIAS 155248-3729
A10: ESTADO DE CUENTAS Y PRORRATEO DE GASTOS AL 31/05/2026 | Z10: compensa
A11: AVISO DE PAGO : FECHA DE VENCIMIENTO 15/06/2026
Z13: Cobranza | AB13: Saldo Obra | AD13: UF1 Saldo
A14: DTO | B14: U.F. | C14: DTO | D14: NOMBRE | E14: SALDO ANTERIOR | F14: SU PAGO | G14: % A | H14: %B | L14: EXP. A | M14: EXP. B | N14: CABLE | O14: OTROS | P14: TOTALES DEL MES | Q14: DEUDA | R14: INTERE-SES | S14: TOTAL | T14: FONDO | U14: OBSERVACIONES | V14: OBSERVACIONES | W14: U.F. | X14: Dif | Y14: S/ liquid | Z14: BANCO | AA14: EFVO | AB14: BANCO | AC14: EFVO | AD14: BANCO | AE14: EFVO
A15: Local | B15: 1 | C15: 1-A | D15: Casa Lopez | E15: =+Y15 -> 25146047 | F15: =-Z15-AA15 -> 0 | G15: 17.08 | H15: 0 | I15: =+(G15+H15)/2 -> 8.54 | J15: =+(0.0631221170186939)*100 -> 6.3122117 | K15: =+I15-J15 -> 2.2277883 | L15: =+$L$25*G15/100 -> 1854854.1 | M15: =+$L$25*H15/100 -> 0 | N15: 0 | O15: 0 | P15: =SUM(L15:N15) -> 1854854.1 | Q15: =+INTERESES!D9+INTERESES!E10+INTERESES!F11+INTERESES!G12+INTERESES!H13+INTERESES!I14+INTERESES!J15+INTERESES!K16+INTERESES!L17+INTERESES!M18+INTERESES!N19+INTERESES!O20+INTERESES!P21+INTERESES!Q22+INTERESES!R23+INTERESES!S24+INTERESES!T25+INTERESES!U26+INTERESES!V27+INTERESES!W28+INTERESES!X29+INTERESES!Y30+INTERESES!Z31+INTERESES!AA32+INTERESES!AB33+INTERESES!AC34+INTERESES!AD35+INTERESES!AE36+INTERESES!AF37+INTERESES!AG38+INTERESES!AH39+INTERESES!AI40+INTERESES!AJ41+INTERESES!AK42+INTERESES!AL43+INTERESES!AM44+INTERESES!AN45+INTERESES!AO46+INTERESES!AP47+INTERESES!AQ48+INTERESES!AR49+INTERESES!AS50+INTERESES!AT51+INTERESES!AU52+INTERESES!AV53+INTERESES!AW54+INTERESES!AX55+INTERESES!AY56+INTERESES!AZ57+INTERESES!BA58+INTERESES!BB59+INTERESES!BC60+INTERESES!BD61+INTERESES!BE62+INTERESES!BF63+INTERESES!BG64+INTERESES!BH65+INTERESES!BI66+INTERESES!BJ67+INTERESES!BK68+INTERESES!BL69+INTERESES!BM70+INTERESES!BN71+INTERESES!BO72+INTERESES!BP73+INTERESES!BQ74+INTERESES!BR75+INTERESES!BS76+INTERESES!BT77+INTERESES!BU78+INTERESES!BV79+INTERESES!BW80+INTERESES!BX81+INTERESES!BY82+INTERESES!BZ83+INTERESES!CA84+INTERESES!CB85+INTERESES!CC86+INTERESES!CD87+INTERESES!CE88+INTERESES!CF89+INTERESES!CG90+INTERESES!CH91+INTERESES!CI92+INTERESES!CJ93+INTERESES!CK94+INTERESES!CL95+INTERESES!CM96+INTERESES!CN97+INTERESES!CO98+INTERESES!CP99+INTERESES!CQ100+INTERESES!CR101+INTERESES!CS102+INTERESES!CT103+INTERESES!CU104+INTERESES!CV105+INTERESES!CW106+INTERESES!CX107+INTERESES!CY108 -> 16679327 | R15: =+INTERESES!DB109 -> 8967099.7 | S15: =+P15+Q15+R15 -> 27501281 | T15: 0 | W15: 1 | X15: =+Y15-Z15-AA15-AB15-AC15-AD15-AE15 -> 25146047 | Y15: 25146047 | AF15: =+R15 -> 8967099.7 | AG15: 0 | AH15: =+AF15-AG15 -> 8967099.7 | AJ15: =+S15-Z15 -> 27501281 | AK15: =+AJ15/Z15 -> #DIV/0!
A16: Local | B16: =+B15+1 -> 2 | C16: 1-B | D16: Eduardo Sanchez | E16: =+Y16 -> 736215.86 | F16: =-Z16-AA16 -> -736216 | G16: 17.08 | H16: 0 | I16: =+(G16+H16)/2 -> 8.54 | J16: =+(0.0407865986890022)*100 -> 4.0786599 | K16: =+I16-J16 -> 4.4613401 | L16: =+$L$25*G16/100 -> 1854854.1 | M16: =+$L$25*H16/100 -> 0 | N16: 0 | O16: 0 | P16: =SUM(L16:N16) -> 1854854.1 | Q16: 0 | R16: 0 | S16: =SUM(P16:R16) -> 1854854.1 | T16: 0 | W16: =+W15+1 -> 2 | X16: =+Y16-Z16-AA16-AB16-AC16-AD16-AE16 -> -0.14116 | Y16: 736215.86 | Z16: 736216 | AF16: =+R16 -> 0 | AG16: 0 | AH16: =+AF16-AG16 -> 0 | AJ16: =+S16-Z16 -> 1118638.1 | AK16: =+AJ16/Z16 -> 1.5194428 | AN16: soporte@casasanchez.com.ar
A17: 1A | B17: =+B16+1 -> 3 | C17: 2-A | D17: Benjamin Fernandez | E17: =+Y17 -> 367327.54 | F17: =-Z17-AA17 -> -397028 | G17: 8.19 | H17: 12.44 | I17: =+(G17+H17)/2 -> 10.315 | J17: =+(0.0485554746297645)*100 -> 4.8555475 | K17: =+I17-J17 -> 5.4594525 | L17: =+$L$25*G17/100 -> 889417.74 | M17: =+$M$25*H17/100 -> 15550 | N17: 0 | O17: 0 | P17: =SUM(L17:N17) -> 904967.74 | Q17: -29700 | R17: 0 | S17: =SUM(P17:R17) -> 875267.74 | T17: 0 | W17: =+W16+1 -> 3 | X17: =+Y17-Z17-AA17-AB17-AC17-AD17-AE17 -> -29700.461 | Y17: 367327.54 | Z17: =764356-367328 -> 397028 | AF17: =+R17 -> 0 | AG17: 0 | AH17: =+AF17-AG17 -> 0 | AJ17: =+S17-Z17 -> 478239.74 | AK17: =+AJ17/Z17 -> 1.2045491 | AN17: lippifranco0@gmail.com
A18: 1B | B18: =+B17+1 -> 4 | C18: 2-B | D18: Franco Lippi | E18: =+Y18 -> 367327.54 | F18: =-Z18-AA18 -> -367328 | G18: 8.19 | H18: 12.44 | I18: =+(G18+H18)/2 -> 10.315 | J18: =+(0.0405438213158534)*100 -> 4.0543821 | K18: =+I18-J18 -> 6.2606179 | L18: =+$L$25*G18/100 -> 889417.74 | M18: =+$M$25*H18/100 -> 15550 | N18: 0 | O18: 0 | P18: =SUM(L18:N18) -> 904967.74 | Q18: 0 | R18: 0 | S18: =SUM(P18:R18) -> 904967.74 | T18: 0 | W18: =+W17+1 -> 4 | X18: =+Y18-Z18-AA18-AB18-AC18-AD18-AE18 -> -0.46113 | Y18: 367327.54 | Z18: 367328 | AF18: =+R18 -> 0 | AG18: 0 | AH18: =+AF18-AG18 -> 0 | AJ18: =+S18-Z18 -> 537639.74 | AK18: =+AJ18/Z18 -> 1.4636503 | AN18: lippifranco0@gmail.com
A19: 2C | B19: =+B18+1 -> 5 | C19: 3-A | D19: Antonella Denegri | E19: =+Y19 -> 370913.86 | F19: =-Z19-AA19 -> -370914 | G19: 8.27 | H19: 12.56 | I19: =+(G19+H19)/2 -> 10.415 | J19: =+(0.0490410293760622)*100 -> 4.9041029 | K19: =+I19-J19 -> 5.5108971 | L19: =+$L$25*G19/100 -> 898105.58 | M19: =+$M$25*H19/100 -> 15700 | N19: 0 | O19: 0 | P19: =SUM(L19:N19)+O19 -> 913805.58 | Q19: 0 | R19: 0 | S19: =SUM(P19:R19) -> 913805.58 | T19: 0 | W19: =+W18+1 -> 5 | X19: =+Y19-Z19-AA19-AB19-AC19-AD19-AE19 -> -0.14329 | Y19: 370913.86 | Z19: 370914 | AF19: =+R19 -> 0 | AG19: 0 | AH19: =+AF19-AG19 -> 0 | AJ19: =+S19-Z19 -> 542891.58 | AK19: =+AJ19/Z19 -> 1.4636589 | AN19: audinomarta@yahoo.com.ar
A20: 2D | B20: =+B19+1 -> 6 | C20: 3-B | D20: Ana Isabel Pirro | E20: =+Y20 -> 370913.86 | F20: =-Z20-AA20 -> -370914 | G20: 8.27 | H20: 12.56 | I20: =+(G20+H20)/2 -> 10.415 | J20: =+(0.0407865986890022)*100 -> 4.0786599 | K20: =+I20-J20 -> 6.3363401 | L20: =+$L$25*G20/100 -> 898105.58 | M20: =+$M$25*H20/100 -> 15700 | N20: 0 | O20: 0 | P20: =SUM(L20:N20) -> 913805.58 | Q20: 0 | R20: 0 | S20: =SUM(P20:R20) -> 913805.58 | T20: 0 | W20: =+W19+1 -> 6 | X20: =+Y20-Z20-AA20-AB20-AC20-AD20-AE20 -> -0.14329 | Y20: 370913.86 | Z20: 370914 | AF20: =+R20 -> 0 | AG20: 0 | AH20: =+AF20-AG20 -> 0 | AJ20: =+S20-Z20 -> 542891.58 | AK20: =+AJ20/Z20 -> 1.4636589 | AM20: Transferencia Recibida - De Renki/ Marcia Aleja / Enero 2021 - Exp / 27242954128 | AN20: anabel.pirro@gmail.com | AO20: Transferencia Recibida - De Martin/morales Manuel / 2 D - Exp / 23252272879
A21: 3E | B21: =+B20+1 -> 7 | C21: 4-A | D21: Leandro Acero | E21: =+Y21 -> 374500.17 | F21: =-Z21-AA21 -> -374500 | G21: 8.35 | H21: 12.68 | I21: =+(G21+H21)/2 -> 10.515 | J21: =+(0.0490410293760622)*100 -> 4.9041029 | K21: =+I21-J21 -> 5.6108971 | L21: =+$L$25*G21/100 -> 906793.42 | M21: =+$M$25*H21/100 -> 15850 | N21: 0 | O21: 0 | P21: =SUM(L21:N21) -> 922643.42 | Q21: 0 | R21: 0 | S21: =SUM(P21:R21) -> 922643.42 | T21: 0 | W21: =+W20+1 -> 7 | X21: =+Y21-Z21-AA21-AB21-AC21-AD21-AE21 -> 0.17455 | Y21: 374500.17 | Z21: 374500 | AF21: =+R21 -> 0 | AG21: 0 | AH21: =+AF21-AG21 -> 0 | AJ21: =+S21-Z21 -> 548143.42 | AK21: =+AJ21/Z21 -> 1.4636673 | AM21: lomas/acero | AN21: escribaniaacero@hotmail.com.ar
A22: 3F | B22: =+B21+1 -> 8 | C22: 4-B | D22: Jose A. Montans | E22: =+Y22 -> 374500.17 | F22: =-Z22-AA22 -> -374500 | G22: 8.35 | H22: 12.68 | I22: =+(G22+H22)/2 -> 10.515 | J22: =+(0.041029376062151)*100 -> 4.1029376 | K22: =+I22-J22 -> 6.4120624 | L22: =+$L$25*G22/100 -> 906793.42 | M22: =+$M$25*H22/100 -> 15850 | N22: 0 | O22: 0 | P22: =SUM(L22:N22) -> 922643.42 | Q22: 0 | R22: 0 | S22: =SUM(P22:R22) -> 922643.42 | T22: 0 | W22: =+W21+1 -> 8 | X22: =+Y22-Z22-AA22-AB22-AC22-AD22-AE22 -> 0.17455 | Y22: 374500.17 | Z22: 331640 | AA22: =+LIQ!G58 -> 42860 | AF22: =+R22 -> 0 | AG22: 0 | AH22: =+AF22-AG22 -> 0 | AJ22: =+S22-738 -> 921905.42 | AK22: =+AJ22/738 -> 1249.1943 | AN22: susanabveiga@hotmail.com
A23: 4G | B23: =+B22+1 -> 9 | C23: 5-A | D23: Miguel A. Machinandiarena | E23: =+Y23 -> 363741.22 | F23: =-Z23-AA23 -> -363741 | G23: 8.11 | H23: 12.32 | I23: =+(G23+H23)/2 -> 10.215 | J23: =+(205/4119)*100 -> 4.9769361 | K23: =+I23-J23 -> 5.2380639 | L23: =+$L$25*G23/100 -> 880729.89 | M23: =+$M$25*H23/100 -> 15400 | N23: 0 | O23: 0 | P23: =SUM(L23:N23) -> 896129.89 | Q23: 0 | R23: 0 | S23: =SUM(P23:R23) -> 896129.89 | T23: 0 | W23: =+W22+1 -> 9 | X23: =+Y23-Z23-AA23-AB23-AC23-AD23-AE23 -> 0.22103 | Y23: 363741.22 | Z23: 363741 | AF23: =+R23 -> 0 | AG23: 0 | AH23: =+AF23-AG23 -> 0 | AJ23: =+S23-717 -> 895412.89 | AK23: =+AJ23/717 -> 1248.8325 | AN23: machifumigaciones@hotmail.com
A24: 4H | B24: =+B23+1 -> 10 | C24: 5-B | D24: Olivier Liem | E24: =+Y24 -> 1066890.5 | F24: =-Z24-AA24 -> 0 | G24: 8.11 | H24: 12.32 | I24: =+(G24+H24)/2 -> 10.215 | J24: =+(0.0422432629278951)*100 -> 4.2243263 | K24: =+I24-J24 -> 5.9906737 | L24: =+$L$25*G24/100 -> 880729.89 | M24: =+$M$25*H24/100 -> 15400 | N24: 0 | O24: 0 | P24: =SUM(L24:N24) -> 896129.89 | Q24: =+INTERESES!CV141+INTERESES!CW142+INTERESES!CX143+INTERESES!CY144 -> 1046410.5 | R24: =+INTERESES!DB145 -> 51872.391 | S24: =SUM(P24:R24) -> 1994412.7 | T24: 0 | W24: =+W23+1 -> 10 | X24: =+Y24-Z24-AA24-AB24-AC24-AD24-AE24 -> 1066890.5 | Y24: 1066890.5 | AF24: =+R24 -> 51872.391 | AG24: 43.012634 | AH24: =+AF24-AG24 -> 51829.378 | AI24: cob y genrera | AJ24: =+S24-590 -> 1993822.7 | AK24: =+AJ24/590 -> 3379.3606 | AN24: olivier.liem@yahoo.fr
D25: TOTALES | E25: =SUM(E15:E24) -> 29538378 | F25: =SUM(F15:F24) -> -3355141 | G25: =SUM(G15:G24) -> 100 | H25: =SUM(H15:H24) -> 100 | I25: =SUM(I15:I24) -> 100 | J25: =SUM(J15:J24) -> 46.491867 | K25: =SUM(K15:K24) -> 53.508133 | L25: =+LIQ!G78-LIQ!G39 -> 10859801 | M25: =+LIQ!G39 -> 125000 | N25: =SUM(N15:N24) -> 0 | O25: =SUM(O15:O24) -> 0 | P25: =SUM(P15:P24) -> 10984801 | Q25: =SUM(Q15:Q24) -> 17696038 | R25: =SUM(R15:R24) -> 9018972.1 | S25: =SUM(S15:S24) -> 37699811 | X25: =+Y25-Z25-AA25 -> 26183237 | Y25: 29538378 | Z25: =SUM(Z15:Z24) -> 3312281 | AA25: =SUM(AA15:AA24) -> 42860 | AB25: =SUM(AB15:AB24) -> 0 | AC25: =SUM(AC15:AC24) -> 0 | AD25: =SUM(AD15:AD24) -> 0 | AE25: =SUM(AE15:AE24) -> 0 | AF25: =+R25 -> 9018972.1 | AG25: 43.012634 | AH25: =+AF25-AG25 -> 9018929.1
Z26: 0
A27: LAS EXPENSAS VENCEN EL DIA 15. PAGO FUERA DE TERMINO 3% DE INTERÉS MENSUAL | U27: =60393.6-50960.07-1482.12+84 -> 8035.41 | Z27: =+Z25+AA25 -> 3355141 | AF27: 7942
Z29: 2116582
A30: FORMAS DE PAGO: | Z30: =+Z27-Z29 -> 1238559
A31: Depósito o transferencia:
A32: Titular: | D32: CONSORCIO DE PROP. LIMA 461
A33: Banco: | D33: SANTANDER
A34: N°Cuenta: | D34: Cta. Cte. $ N°210-001950/3 | U34: =+LIQ!G83 -> 3355141 | Z34: =+Z25+AA25 -> 3355141 | AB34: =+AB25+AC25 -> 0
A35: CBU: | D35: 0720210220000000195036 | U35: =+U27-U34 -> -3347105.6 | Z35: 444270
A36: Alias: | D36: BOCHA.CARDO.COPA
A39: DATOS DE JUICIOS
A40: Conf. Art. 10 inc. h Ley N°941
A42: CARATULA: Cons. de Prop. Lima 461/67/73 c/Lopez Jose y otro s /Ejecución de Expensas
A43: N° EXPEDIENTE: 68063/2018
A44: JUZGADO/SECRETARÍA: Juzgado Civil N° 75
A45: ESTADO: embargo trabado
A46: MONTO RECLAMADO:
A49: MANUAL DE BUENAS PRÁCTICAS CONSORCIALES
A50: https://buenosaires.gob.ar/sites/default/files/2025-02/Manual%20buenas%20pr%C3%A1cticas%20consorciales_0.pdf
...

Sheet INTERESES
A2: =+'RES CUENTA'!#REF! -> #REF!
A7: U.F. | B7: DTO | C7: NOMBRE | D7: 43101 | E7: 43132 | F7: 43160 | G7: 43191 | H7: 43221 | I7: 43252 | J7: 43282 | K7: 43313 | L7: 43344 | M7: 43374 | N7: 43405 | O7: 43435 | P7: 43466 | Q7: 43497 | R7: 43525 | S7: 43556 | T7: 43586 | U7: 43617 | V7: 43647 | W7: 43678 | X7: 43709 | Y7: 43739 | Z7: 43770 | AA7: 43800 | AB7: 43831 | AC7: 43862 | AD7: 43891 | AE7: 43922 | AF7: 43952 | AG7: 43983 | AH7: 44013 | AI7: 44044 | AJ7: 44075 | AK7: 44105 | AL7: 44136 | AM7: 44166 | AN7: 44197 | AO7: 44228 | AP7: 44256 | AQ7: 44287 | AR7: 44317 | AS7: 44348 | AT7: 44378 | AU7: 44409 | AV7: 44440 | AW7: 44470 | AX7: 44501 | AY7: 44531 | AZ7: 44562 | BA7: 44593 | BB7: 44621 | BC7: 44652 | BD7: 44682 | BE7: 44713 | BF7: 44743 | BG7: 44774 | BH7: 44805 | BI7: 44835 | BJ7: 44866 | BK7: 44896 | BL7: 44927 | BM7: 44958 | BN7: 44986 | BO7: 45017 | BP7: 45047 | BQ7: 45078 | BR7: 45108 | BS7: 45139 | BT7: 45170 | BU7: 45200 | BV7: 45231 | BW7: 45261 | BX7: 45292 | BY7: 45323 | BZ7: 45352 | CA7: 45383 | CB7: 45413 | CC7: 45444 | CD7: 45474 | CE7: 45505 | CF7: 45536 | CG7: 45566 | CH7: 45597 | CI7: 45627 | CJ7: 45658 | CK7: 45689 | CL7: 45717 | CM7: 45748 | CN7: 45778 | CO7: 45809 | CP7: 45839 | CQ7: 45870 | CR7: 45901 | CS7: 45931 | CT7: 45962 | CU7: 45992 | CV7: 46023 | CW7: 46054 | CX7: 46082 | CY7: 46113 | CZ7: TASA | DA7: DIAS | DB7: INTERES
A9: 1 | C9: =+'RES CUENTA'!D15 -> Casa Lopez | D9: =+'[2]RES CUENTA'!$O$18 -> 6423.3473 | CZ9: 0.03 | DA9: 3000 | DB9: =+D9*CZ9/30*DA9 -> 19270.042 | DC9: =+DA9-DA10 -> 30 | DD9: =+DA9/365 -> 8.2191781
E10: =+'[3]RES CUENTA'!$O$18 -> 6906.0213 | CZ10: 0.03 | DA10: 2970 | DB10: =+E10*CZ10/30*DA10 -> 20510.883 | DC10: =+DA10-DA11 -> 30
F11: =+'[4]RES CUENTA'!$O$18 -> 9084.4506 | CZ11: 0.03 | DA11: 2940 | DB11: =+F11*CZ11/30*DA11 -> 26708.285 | DC11: =+DA11-DA12 -> 30
G12: =+'[5]RES CUENTA'!$O$18 -> 10009.988 | CZ12: 0.03 | DA12: 2910 | DB12: =+G12*CZ12/30*DA12 -> 29129.067 | DC12: =+DA12-DA13 -> 30
H13: =+'[6]RES CUENTA'!$O$18 -> 9524.0369 | CZ13: 0.03 | DA13: 2880 | DB13: =+H13*CZ13/30*DA13 -> 27429.226 | DC13: =+DA13-DA14 -> 30
I14: =+'[7]RES CUENTA'!$O$18 -> 9455.2233 | CZ14: 0.03 | DA14: 2850 | DB14: =+I14*CZ14/30*DA14 -> 26947.386 | DC14: =+DA14-DA15 -> 30
J15: =+'[8]RES CUENTA'!$O$18 -> 7258.1238 | CZ15: 0.03 | DA15: 2820 | DB15: =+J15*CZ15/30*DA15 -> 20467.909 | DC15: =+DA15-DA16 -> 30
K16: =+'[9]RES CUENTA'!$O$18 -> 10081.522 | CZ16: 0.03 | DA16: 2790 | DB16: =+K16*CZ16/30*DA16 -> 28127.447 | DC16: =+DA16-DA17 -> 30
L17: =+'[10]RES CUENTA'!$O$18 -> 9702.7529 | CZ17: 0.03 | DA17: 2760 | DB17: =+L17*CZ17/30*DA17 -> 26779.598 | DC17: =+DA17-DA18 -> 30
M18: =+'[11]RES CUENTA'!$O$18 -> 14227.098 | CZ18: 0.03 | DA18: 2730 | DB18: =+M18*CZ18/30*DA18 -> 38839.978 | DC18: =+DA18-DA19 -> 30
N19: =+'[12]RES CUENTA'!$O$18 -> 14621.914 | CZ19: 0.03 | DA19: 2700 | DB19: =+N19*CZ19/30*DA19 -> 39479.168 | DC19: =+DA19-DA20 -> 30
O20: =+'[13]RES CUENTA'!$O$18 -> 15154.505 | CZ20: 0.03 | DA20: 2670 | DB20: =+O20*CZ20/30*DA20 -> 40462.529 | DC20: =+DA20-DA21 -> 30
P21: =+'[14]RES CUENTA'!$O$18 -> 14019.754 | CZ21: 0.03 | DA21: 2640 | DB21: =+P21*CZ21/30*DA21 -> 37012.15 | DC21: =+DA21-DA22 -> 30
Q22: =+'[15]RES CUENTA'!$O$18 -> 13731.776 | CZ22: 0.03 | DA22: 2610 | DB22: =+Q22*CZ22/30*DA22 -> 35839.936 | DC22: =+DA22-DA23 -> 30
R23: =+'[16]RES CUENTA'!$O$18 -> 14197.886 | CZ23: 0.03 | DA23: 2580 | DB23: =+R23*CZ23/30*DA23 -> 36630.546 | DC23: =+DA23-DA24 -> 30
S24: =+'[17]RES CUENTA'!$O$18 -> 13290.12 | CZ24: 0.03 | DA24: 2550 | DB24: =+S24*CZ24/30*DA24 -> 33889.805 | DC24: =+DA24-DA25 -> 30
T25: =+'[18]RES CUENTA'!$O$18 -> 14125.29 | CZ25: 0.03 | DA25: 2520 | DB25: =+T25*CZ25/30*DA25 -> 35595.73 | DC25: =+DA25-DA26 -> 30
U26: =+'[19]RES CUENTA'!$O$18 -> 17870.851 | CZ26: 0.03 | DA26: 2490 | DB26: =+U26*CZ26/30*DA26 -> 44498.419 | DC26: =+DA26-DA27 -> 30
V27: =+'[20]RES CUENTA'!$O$18 -> 12458.019 | CZ27: 0.03 | DA27: 2460 | DB27: =+V27*CZ27/30*DA27 -> 30646.727 | DC27: =+DA27-DA28 -> 30
W28: =+'[21]RES CUENTA'!$O$18 -> 12797.668 | CZ28: 0.03 | DA28: 2430 | DB28: =+W28*CZ28/30*DA28 -> 31098.333 | DC28: =+DA28-DA29 -> 30
X29: =+'[22]RES CUENTA'!$O$18 -> 12868.024 | CZ29: 0.03 | DA29: 2400 | DB29: =+X29*CZ29/30*DA29 -> 30883.257 | DC29: =+DA29-DA30 -> 30
Y30: =+'[23]RES CUENTA'!$O$18 -> 15642.94 | CZ30: 0.03 | DA30: 2370 | DB30: =+Y30*CZ30/30*DA30 -> 37073.769 | DC30: =+DA30-DA31 -> 30
Z31: =+'[24]RES CUENTA'!$O$18 -> 16047.563 | CZ31: 0.03 | DA31: 2340 | DB31: =+Z31*CZ31/30*DA31 -> 37551.297 | DC31: =+DA31-DA32 -> 30
AA32: =+'[25]RES CUENTA'!$O$18 -> 16392.666 | CZ32: 0.03 | DA32: 2310 | DB32: =+AA32*CZ32/30*DA32 -> 37867.059 | DC32: =+DA32-DA33 -> 30
AB33: =+'[26]RES CUENTA'!$O$18 -> 14379.2 | CZ33: 0.03 | DA33: 2280 | DB33: =+AB33*CZ33/30*DA33 -> 32784.577 | DC33: =+DA33-DA34 -> 30
AC34: =+'[27]RES CUENTA'!$O$18 -> 14729.463 | CZ34: 0.03 | DA34: 2250 | DB34: =+AC34*CZ34/30*DA34 -> 33141.293 | DC34: =+DA34-DA35 -> 30
AD35: =+'[28]RES CUENTA'!$O$18 -> 15688.46 | CZ35: 0.03 | DA35: 2220 | DB35: =+AD35*CZ35/30*DA35 -> 34828.381 | DC35: =+DA35-DA36 -> 30
AE36: =+'[29]RES CUENTA'!$O$18 -> 15477.466 | CZ36: 0.03 | DA36: 2190 | DB36: =+AE36*CZ36/30*DA36 -> 33895.65 | DC36: =+DA36-DA37 -> 30
AF37: =+'[30]RES CUENTA'!$O$18 -> 14246.361 | CZ37: 0.03 | DA37: 2160 | DB37: =+AF37*CZ37/30*DA37 -> 30772.14 | DC37: =+DA37-DA38 -> 30
AG38: =+'[31]RES CUENTA'!$O$18 -> 14145.844 | CZ38: 0.03 | DA38: 2130 | DB38: =+AG38*CZ38/30*DA38 -> 30130.647 | DC38: =+DA38-DA39 -> 30
AH39: =+'[32]RES CUENTA'!$O$18 -> 14164.854 | CZ39: 0.03 | DA39: 2100 | DB39: =+AH39*CZ39/30*DA39 -> 29746.193 | DC39: =+DA39-DA40 -> 30
AI40: =+'[33]RES CUENTA'!$O$18 -> 18922.872 | CZ40: 0.03 | DA40: 2070 | DB40: =+AI40*CZ40/30*DA40 -> 39170.345 | DC40: =+DA40-DA41 -> 30
AJ41: =+'[34]RES CUENTA'!$O$18 -> 17793.58 | CZ41: 0.03 | DA41: 2040 | DB41: =+AJ41*CZ41/30*DA41 -> 36298.904 | DC41: =+DA41-DA42 -> 30
AK42: =+'[35]RES CUENTA'!$O$18 -> 17624.282 | CZ42: 0.03 | DA42: 2010 | DB42: =+AK42*CZ42/30*DA42 -> 35424.806 | DC42: =+DA42-DA43 -> 30
AL43: =+'[36]RES CUENTA'!$O$18 -> 17478.324 | CZ43: 0.03 | DA43: 1980 | DB43: =+AL43*CZ43/30*DA43 -> 34607.082 | DC43: =+DA43-DA44 -> 30
AM44: =+'[37]RES CUENTA'!$O$18 -> 20447.126 | CZ44: 0.03 | DA44: 1950 | DB44: =+AM44*CZ44/30*DA44 -> 39871.895 | DC44: =+DA44-DA45 -> 30
AN45: =+'[38]RES CUENTA'!$O$18 -> 19619.487 | CZ45: 0.03 | DA45: 1920 | DB45: =+AN45*CZ45/30*DA45 -> 37669.415 | DC45: =+DA45-DA46 -> 30
AO46: =+'[39]RES CUENTA'!$O$18 -> 20899.616 | CZ46: 0.03 | DA46: 1890 | DB46: =+AO46*CZ46/30*DA46 -> 39500.274 | DC46: =+DA46-DA47 -> 30
...

Sheet SUELDO
A2: EMPLEADOR: CONS. DE PROP. BERUTI 4575/77 | F2: CUIT: 30-70807291-1
A3: Domicilio: Beruti 4575/77 | F3: Recibo: 1 ORIGINAL
B4: 1425 - Capital Federal | F4: Cuil: 23-11424220-9
A5: PERIODO | B5: APELLIDO Y NOMBRES | F5: Categoria | G5: Legajo
A6: 37653 | B6: OSUNA CLAUDIO R. | F6: 0-03 | G6: 1
A7: BANCO | B7: PERIODO DEPOSITADO | E7: FECHA | F7: TAREA | G7: INGRESO
A8: Nación | B8: Febrero 2003 | E8: 37687 | F8: Enc.Perm c/viv | G8: 37518
A9: CONCEPTOS | E9: UNIDADES | F9: REMUNERAC. | G9: DESCUENT.
A11: BASICO | F11: =374.4 -> 374.4 | I11: feriados,dom
A12: RETIRO DE RESIDUOS | E12: 15 | F12: =+E12*1.26 -> 18.9 | I12: 6
A13: PLUS JARDIN | F13: =16.98 -> 16.98 | I13: 5 | J13: DIAS
A14: PLUS COCHERA | F14: =16.98 -> 16.98 | I14: =+I12*I13 -> 30
A15: DEC.2641/02 | F15: 150 | I15: GRATIFICACION | O15: =+H17+109.74 -> 1832.43
A16: RET. JUBILACION | C16: 7 | D16: % | F16: - | G16: =+$H$17*C16/100 -> 120.5883 | I16: DS NORMALES | K16: 1 | L16: =427.26/30*1 -> 14.242
A17: LEY N 19032 | C17: 3 | D17: % | F17: - | G17: =+$H$17*C17/100 -> 51.6807 | H17: =895.36+727.33+100 -> 1722.69 | I17: HS EXTRAS | K17: 24 | L17: =427.26/200*2*24 -> 102.5424
A18: OBRA SOCIAL | C18: 2.7 | D18: % | F18: - | G18: =+$H$17*C18/100 -> 46.51263 | L18: =+L16+L17 -> 116.7844
A19: ANSSAL | C19: 0.3 | D19: % | F19: - | G19: =+$H$17*C19/100 -> 5.16807 | H19: =SUM(G16:G19) -> 223.9497
A20: CUOTA SINDICAL | C20: 2 | D20: % | F20: - | G20: =+$H$17*C20/100 -> 34.4538 | H20: =59.38+8.76+25.92+5.2+3.5+31.53 -> 134.29 | I20: SETIEMBRE
A21: CAJA PROT FAMILIA | C21: 1 | D21: % | F21: - | G21: =+$H$17*C21/100 -> 17.2269 | H21: =134.29/583.86 -> 0.23000377 | I21: DS NORMALES | K21: 2.5 | L21: =427.26/30*2.5 -> 35.605
H22: =+H21*H17 -> 396.22519 | I22: HS EXTRAS | K22: 40 | L22: =427.26/200*2*40 -> 170.904
D23: TOTAL BRUTO | F23: =SUM(F11:F22) -> 577.26 | H23: =+H22+H19 -> 620.17489
D24: TOTAL DESCUENTOS | F24: - | G24: =SUM(G16:G22) -> 275.6304
D25: TOTAL NETO | F25: - | G25: =+F23-G24 -> 301.6296
D26: REDONDEO | F26: - | G26: =ROUND(G25,0) -> 302
D27: SON PESOS:
A28: FIRMA DEL EMPLEADO | D28: SEICIENTOS OCHENTA Y OCHO
A29: Recibí de la firma cuyo rubro se indica arriba el importe neto de esta liquidación en pago de mi
A30: remuneración correspondiente al período indicado y duplicado de la misma.
A35: EMPLEADOR: CONS. DE PROP. BERUTI 4575/77 | F35: CUIT: 30-70807291-1
A36: Domicilio: Beruti 4575/77 | F36: Recibo: 2 DUPLICADO
B37: 1425 - Capital Federal | F37: Cuil: 23-11424220-9
A38: PERIODO | B38: APELLIDO Y NOMBRES | F38: Categoria | G38: Legajo
A39: =+A6 -> 37653 | B39: OSUNA CLAUDIO R. | F39: 0-03 | G39: 1
A40: BANCO | B40: PERIODO DEPOSITADO | E40: FECHA | F40: TAREA | G40: INGRESO
A41: Nación | B41: Febrero 2003 | E41: =+E8 -> 37687 | F41: Enc.Perm c/viv | G41: 37518
A42: CONCEPTOS | E42: UNIDADES | F42: REMUNERAC. | G42: DESCUENT.
A44: BASICO | F44: =374.4 -> 374.4
A45: HORAS EXTRAS 100% | E45: =3+3+8+3+8+3+8+3+8 -> 47 | F45: =+#REF! -> #REF!
A46: =+#REF! -> #REF! | E46: =+#REF! -> #REF! | F46: =+#REF! -> #REF!
A47: RETIRO DE RESIDUOS | E47: 15 | F47: =+E47*1.26 -> 18.9
...

Sheet RECIBOS (2)
B1: =+LIQ!H1 -> 46143 | D1: 46188 | E1: Lima 461 C:A:B:A: | F1: P/Depósito/transferencia en Bco Santander Rio
B2: =+'RES CUENTA'!D15 -> Casa Lopez | C2: =+'RES CUENTA'!G15 -> 17.08 | D2: =+'RES CUENTA'!B15 -> 1 | E2: =+'RES CUENTA'!H15 -> 0 | F2: Cta. Cte. $ N° 210-1950/3 | H2: 210-1950/3
B3: =+'RES CUENTA'!D16 -> Eduardo Sanchez | C3: =+'RES CUENTA'!G16 -> 17.08 | D3: =+'RES CUENTA'!B16 -> 2 | E3: =+'RES CUENTA'!H16 -> 0 | F3: CBU 0720210220000000195036
B4: =+'RES CUENTA'!D17 -> Benjamin Fernandez | C4: =+'RES CUENTA'!G17 -> 8.19 | D4: =+'RES CUENTA'!B17 -> 3 | E4: =+'RES CUENTA'!H17 -> 12.44 | F4: =+LIQ!G4 -> CUIT: 30-53267348-4
B5: =+'RES CUENTA'!D18 -> Franco Lippi | C5: =+'RES CUENTA'!G18 -> 8.19 | D5: =+'RES CUENTA'!B18 -> 4 | E5: =+'RES CUENTA'!H18 -> 12.44
B6: =+'RES CUENTA'!D19 -> Antonella Denegri | C6: =+'RES CUENTA'!G19 -> 8.27 | D6: =+'RES CUENTA'!B19 -> 5 | E6: =+'RES CUENTA'!H19 -> 12.56
B7: =+'RES CUENTA'!D20 -> Ana Isabel Pirro | C7: =+'RES CUENTA'!G20 -> 8.27 | D7: =+'RES CUENTA'!B20 -> 6 | E7: =+'RES CUENTA'!H20 -> 12.56
B8: =+'RES CUENTA'!D21 -> Leandro Acero | C8: =+'RES CUENTA'!G21 -> 8.35 | D8: =+'RES CUENTA'!B21 -> 7 | E8: =+'RES CUENTA'!H21 -> 12.68
B9: =+'RES CUENTA'!D22 -> Jose A. Montans | C9: =+'RES CUENTA'!G22 -> 8.35 | D9: =+'RES CUENTA'!B22 -> 8 | E9: =+'RES CUENTA'!H22 -> 12.68
B10: =+'RES CUENTA'!D23 -> Miguel A. Machinandiarena | C10: =+'RES CUENTA'!G23 -> 8.11 | D10: =+'RES CUENTA'!B23 -> 9 | E10: =+'RES CUENTA'!H23 -> 12.32
B11: =+'RES CUENTA'!D24 -> Olivier Liem | C11: =+'RES CUENTA'!G24 -> 8.11 | D11: =+'RES CUENTA'!B24 -> 10 | E11: =+'RES CUENTA'!H24 -> 12.32
B12: =+'RES CUENTA'!#REF! -> #REF! | C12: =+'RES CUENTA'!#REF! -> #REF! | D12: =+'RES CUENTA'!#REF! -> #REF! | E12: =+'RES CUENTA'!#REF! -> #REF!
B13: =+'RES CUENTA'!#REF! -> #REF! | C13: =+'RES CUENTA'!#REF! -> #REF! | D13: =+'RES CUENTA'!#REF! -> #REF! | E13: =+'RES CUENTA'!#REF! -> #REF!
B14: =+'RES CUENTA'!#REF! -> #REF! | C14: =+'RES CUENTA'!#REF! -> #REF! | D14: =+'RES CUENTA'!#REF! -> #REF! | E14: =+'RES CUENTA'!#REF! -> #REF!
B15: =+'RES CUENTA'!#REF! -> #REF! | C15: =+'RES CUENTA'!#REF! -> #REF! | D15: =+'RES CUENTA'!#REF! -> #REF! | E15: =+'RES CUENTA'!#REF! -> #REF!
B16: =+'RES CUENTA'!#REF! -> #REF! | C16: =+'RES CUENTA'!#REF! -> #REF! | D16: =+'RES CUENTA'!#REF! -> #REF! | E16: =+'RES CUENTA'!#REF! -> #REF!
B17: =+'RES CUENTA'!#REF! -> #REF! | C17: =+'RES CUENTA'!#REF! -> #REF! | D17: =+'RES CUENTA'!#REF! -> #REF! | E17: =+'RES CUENTA'!#REF! -> #REF!
B18: =+'RES CUENTA'!#REF! -> #REF! | C18: =+'RES CUENTA'!#REF! -> #REF! | D18: =+'RES CUENTA'!#REF! -> #REF! | E18: =+'RES CUENTA'!#REF! -> #REF!
B19: =+'RES CUENTA'!#REF! -> #REF! | C19: =+'RES CUENTA'!#REF! -> #REF! | D19: =+'RES CUENTA'!#REF! -> #REF! | E19: =+'RES CUENTA'!#REF! -> #REF!
B20: =+'RES CUENTA'!#REF! -> #REF! | C20: =+'RES CUENTA'!#REF! -> #REF! | D20: =+'RES CUENTA'!#REF! -> #REF! | E20: =+'RES CUENTA'!#REF! -> #REF!
B21: =+'RES CUENTA'!#REF! -> #REF! | C21: =+'RES CUENTA'!#REF! -> #REF! | D21: =+'RES CUENTA'!#REF! -> #REF! | E21: =+'RES CUENTA'!#REF! -> #REF!
B22: =+'RES CUENTA'!#REF! -> #REF! | C22: =+'RES CUENTA'!#REF! -> #REF! | D22: =+'RES CUENTA'!#REF! -> #REF! | E22: =+'RES CUENTA'!#REF! -> #REF!
B23: =+'RES CUENTA'!#REF! -> #REF! | C23: =+'RES CUENTA'!#REF! -> #REF! | D23: =+'RES CUENTA'!#REF! -> #REF! | E23: =+'RES CUENTA'!#REF! -> #REF!
B24: =+'RES CUENTA'!#REF! -> #REF! | C24: =+'RES CUENTA'!#REF! -> #REF! | D24: =+'RES CUENTA'!#REF! -> #REF! | E24: =+'RES CUENTA'!#REF! -> #REF!
C25: =SUM(C2:C24) -> #REF! | E25: =SUM(E2:E24) -> #REF!
E30: =+$B$1 -> 46143 | G30: =+$D$1 -> 46188
B34: =+B2 -> Casa Lopez | E34: =+E1 -> Lima 461 C:A:B:A: | H34: Unid. 1
H35: =+'RES CUENTA'!A15 -> Local
B38: Expensas Gastos A | D38: =+'RES CUENTA'!L25 -> 10859801 | E38: =+'RES CUENTA'!G15 -> 17.08 | F38: =+D38*E38/100 -> 1854854.1
B39: Cable | D39: 0 | E39: 0 | F39: =+D39*E39/100 -> 0
B40: Cuota extra | D40: 0 | E40: 0 | F40: 0
B41: Deuda Anterior | D41: =+'RES CUENTA'!Q15 -> 16679327 | E41: 0 | F41: =+D41 -> 16679327
B42: Intereses | D42: =+'RES CUENTA'!R15 -> 8967099.7 | E42: 0 | F42: =+D42+E42 -> 8967099.7
F43: =SUM(F38:F42) -> 27501281
B49: =+B2 -> Casa Lopez | E49: =+B2 -> Casa Lopez
B51: =+E1 -> Lima 461 C:A:B:A: | D51: =+H34 -> Unid. 1 | E51: =+E1 -> Lima 461 C:A:B:A: | H51: =+D51 -> Unid. 1
D52: =+H52 -> Local | H52: =+H35 -> Local
B54: =+F1 -> P/Depósito/transferencia en Bco Santander Rio
B55: =+F2 -> Cta. Cte. $ N° 210-1950/3
B56: =+F3 -> CBU 0720210220000000195036 | E56: G A | F56: =+F38 -> 1854854.1 | H56: =+D1 -> 46188
...

Sheet RECIBOS
B1: =+LIQ!H1 -> 46143 | D1: 46037 | E1: Lima 461 C:A:B:A: | F1: P/Depósito/transferencia en Bco Santander Rio
B2: =+'RES CUENTA'!D15 -> Casa Lopez | C2: =+'RES CUENTA'!G15 -> 17.08 | D2: =+'RES CUENTA'!B15 -> 1 | E2: =+'RES CUENTA'!H15 -> 0 | F2: Cta. Cte. $ N° 210-1950/3 | H2: 210-1950/3
B3: =+'RES CUENTA'!D16 -> Eduardo Sanchez | C3: =+'RES CUENTA'!G16 -> 17.08 | D3: =+'RES CUENTA'!B16 -> 2 | E3: =+'RES CUENTA'!H16 -> 0 | F3: CBU 0720210220000000195036
B4: =+'RES CUENTA'!D17 -> Benjamin Fernandez | C4: =+'RES CUENTA'!G17 -> 8.19 | D4: =+'RES CUENTA'!B17 -> 3 | E4: =+'RES CUENTA'!H17 -> 12.44 | F4: =+LIQ!G4 -> CUIT: 30-53267348-4
B5: =+'RES CUENTA'!D18 -> Franco Lippi | C5: =+'RES CUENTA'!G18 -> 8.19 | D5: =+'RES CUENTA'!B18 -> 4 | E5: =+'RES CUENTA'!H18 -> 12.44
B6: =+'RES CUENTA'!D19 -> Antonella Denegri | C6: =+'RES CUENTA'!G19 -> 8.27 | D6: =+'RES CUENTA'!B19 -> 5 | E6: =+'RES CUENTA'!H19 -> 12.56
B7: =+'RES CUENTA'!D20 -> Ana Isabel Pirro | C7: =+'RES CUENTA'!G20 -> 8.27 | D7: =+'RES CUENTA'!B20 -> 6 | E7: =+'RES CUENTA'!H20 -> 12.56
B8: =+'RES CUENTA'!D21 -> Leandro Acero | C8: =+'RES CUENTA'!G21 -> 8.35 | D8: =+'RES CUENTA'!B21 -> 7 | E8: =+'RES CUENTA'!H21 -> 12.68
B9: =+'RES CUENTA'!D22 -> Jose A. Montans | C9: =+'RES CUENTA'!G22 -> 8.35 | D9: =+'RES CUENTA'!B22 -> 8 | E9: =+'RES CUENTA'!H22 -> 12.68
B10: =+'RES CUENTA'!D23 -> Miguel A. Machinandiarena | C10: =+'RES CUENTA'!G23 -> 8.11 | D10: =+'RES CUENTA'!B23 -> 9 | E10: =+'RES CUENTA'!H23 -> 12.32
B11: =+'RES CUENTA'!D24 -> Olivier Liem | C11: =+'RES CUENTA'!G24 -> 8.11 | D11: =+'RES CUENTA'!B24 -> 10 | E11: =+'RES CUENTA'!H24 -> 12.32
B12: =+'RES CUENTA'!#REF! -> #REF! | C12: =+'RES CUENTA'!#REF! -> #REF! | D12: =+'RES CUENTA'!#REF! -> #REF! | E12: =+'RES CUENTA'!#REF! -> #REF!
B13: =+'RES CUENTA'!#REF! -> #REF! | C13: =+'RES CUENTA'!#REF! -> #REF! | D13: =+'RES CUENTA'!#REF! -> #REF! | E13: =+'RES CUENTA'!#REF! -> #REF!
B14: =+'RES CUENTA'!#REF! -> #REF! | C14: =+'RES CUENTA'!#REF! -> #REF! | D14: =+'RES CUENTA'!#REF! -> #REF! | E14: =+'RES CUENTA'!#REF! -> #REF!
B15: =+'RES CUENTA'!#REF! -> #REF! | C15: =+'RES CUENTA'!#REF! -> #REF! | D15: =+'RES CUENTA'!#REF! -> #REF! | E15: =+'RES CUENTA'!#REF! -> #REF!
B16: =+'RES CUENTA'!#REF! -> #REF! | C16: =+'RES CUENTA'!#REF! -> #REF! | D16: =+'RES CUENTA'!#REF! -> #REF! | E16: =+'RES CUENTA'!#REF! -> #REF!
B17: =+'RES CUENTA'!#REF! -> #REF! | C17: =+'RES CUENTA'!#REF! -> #REF! | D17: =+'RES CUENTA'!#REF! -> #REF! | E17: =+'RES CUENTA'!#REF! -> #REF!
B18: =+'RES CUENTA'!#REF! -> #REF! | C18: =+'RES CUENTA'!#REF! -> #REF! | D18: =+'RES CUENTA'!#REF! -> #REF! | E18: =+'RES CUENTA'!#REF! -> #REF!
B19: =+'RES CUENTA'!#REF! -> #REF! | C19: =+'RES CUENTA'!#REF! -> #REF! | D19: =+'RES CUENTA'!#REF! -> #REF! | E19: =+'RES CUENTA'!#REF! -> #REF!
B20: =+'RES CUENTA'!#REF! -> #REF! | C20: =+'RES CUENTA'!#REF! -> #REF! | D20: =+'RES CUENTA'!#REF! -> #REF! | E20: =+'RES CUENTA'!#REF! -> #REF!
B21: =+'RES CUENTA'!#REF! -> #REF! | C21: =+'RES CUENTA'!#REF! -> #REF! | D21: =+'RES CUENTA'!#REF! -> #REF! | E21: =+'RES CUENTA'!#REF! -> #REF!
B22: =+'RES CUENTA'!#REF! -> #REF! | C22: =+'RES CUENTA'!#REF! -> #REF! | D22: =+'RES CUENTA'!#REF! -> #REF! | E22: =+'RES CUENTA'!#REF! -> #REF!
B23: =+'RES CUENTA'!#REF! -> #REF! | C23: =+'RES CUENTA'!#REF! -> #REF! | D23: =+'RES CUENTA'!#REF! -> #REF! | E23: =+'RES CUENTA'!#REF! -> #REF!
B24: =+'RES CUENTA'!#REF! -> #REF! | C24: =+'RES CUENTA'!#REF! -> #REF! | D24: =+'RES CUENTA'!#REF! -> #REF! | E24: =+'RES CUENTA'!#REF! -> #REF!
C25: =SUM(C2:C24) -> #REF! | E25: =SUM(E2:E24) -> #REF!
E30: =+$B$1 -> 46143 | G30: =+$D$1 -> 46037
B34: =+B2 -> Casa Lopez | E34: =+E1 -> Lima 461 C:A:B:A: | H34: Unid. 1
H35: =+'RES CUENTA'!A15 -> Local
B38: Expensas Gastos A | D38: =+'RES CUENTA'!L25 -> 10859801 | E38: =+'RES CUENTA'!G15 -> 17.08 | F38: =+D38*E38/100 -> 1854854.1
B39: Cable | D39: 0 | E39: 0 | F39: =+D39*E39/100 -> 0
B40: Cuota extra | D40: 0 | E40: 0 | F40: 0
B41: Deuda Anterior | D41: =+'RES CUENTA'!Q15 -> 16679327 | E41: 0 | F41: =+D41 -> 16679327
B42: Intereses | D42: =+'RES CUENTA'!R15 -> 8967099.7 | E42: 0 | F42: =+D42+E42 -> 8967099.7
F43: =SUM(F38:F42) -> 27501281
B49: =+B2 -> Casa Lopez | E49: =+B2 -> Casa Lopez
B51: =+E1 -> Lima 461 C:A:B:A: | D51: =+H34 -> Unid. 1 | E51: =+E1 -> Lima 461 C:A:B:A: | H51: =+D51 -> Unid. 1
D52: =+H52 -> Local | H52: =+H35 -> Local
B54: =+F1 -> P/Depósito/transferencia en Bco Santander Rio
B55: =+F2 -> Cta. Cte. $ N° 210-1950/3
B56: =+F3 -> CBU 0720210220000000195036 | E56: G A | F56: =+F38 -> 1854854.1 | H56: =+D1 -> 46037
...

Sheet Hoja 3

Sheet Hoja2
A1: Local
A2: enero | B2: 2002 | C2: 593 | D2: 2950
A3: feb | C3: 720 | D3: 3589
A4: abrul | B4: 2002 | C4: 622 | D4: 3100
A6: mayo | C6: 697 | D6: 3472
A7: julio | B7: 2002 | C7: 677 | D7: 3379
A8: agost | C8: 689 | D8: 3430
A9: set | C9: 687 | D9: 3427
A10: dic | B10: 2002 | C10: 667 | D10: 3327
A11: enero | B11: 2003 | C11: 646 | D11: 3219
A12: feb | C12: 881 | D12: 4391
A13: marz | C13: 689 | D13: 3436
A14: abruil | C14: 680
A15: mayo | C15: 780

Sheet Hoja1
A2: CONSORCIO SANTIAGO DEL ESTERO 338
A4: DETERMINACIÓN DE LAS COBRANZAS Y DE LOS SALDOS PENDIENTES DE COBRO AL 06/06/03
A7: Deuda anterior incluye intereses | E7: 60393.6
A8: Cobrado | E8: =-8052.31 -> -8052.31
A9: Deuda anterior (solamente capital) | E9: -50960.07
A10: Intereses pedientes de cobro correspondiente a deuda anterior | E10: =-'RES CUENTA'!#REF!+0.9 -> #REF!
A11: Importe incluido en Cobranzas y no en resumen de cuenta por no haber sido identificado | E11: 100
A12: Control | E12: =SUM(E7:E11) -> #REF!
