Workbook

Sheet LIQ
A1: MIS EXPENSAS- Liquidación de | I1: MES: | J1: 46143
A2: ADMINISTRACION: | H2: CONSORCIO DE PROPIETARIOS:
A3: MARIANO CAUVIN | H3: MONTES DE OCA 1068/1070 C.A.B.A.
A4: AV.BELGRANO 1270 5°A C.A.B.A. | H4: CUIT: 30-66148861-8
A5: masoca_administraciones@hotmail.com | F5: 4381-0014 | H5: CLAVE SUTERH: 23883 | K5: 23883 | L5: clave | M5: 1068
A6: 20-16975070-0 | F6: Responsable Monotributo
A7: R.P.A. N° 470 | F7: URG 155248-3729
B9: PAGOS DEL PERIODO | G9: GASTOS A | H9: GASTOS B | I9: TOTAL | J9: % | L9: EFECTIVO | M9: BANCO | N9: PENDIENTE
L10: EFECTIVO | M10: BANCO | N10: PEND
B11: REMUNERACIONES AL PERSONAL Y CARGAS SOCIALES | I11: 0 | J11: =+I11/$I$57 -> 0 | L11: 0 | M11: =+I11 -> 0 | N11: 0 | O11: =SUM(L11:N11) -> 0
B12: Conf. Art. 10 inc.d Ley N°941
A13: 1 | B13: DETALLE DE SUELDOS Y CARGAS SOCIALES:
B15: PAGOS POR SUMINISTROS, SERVICIOS, ABONOS Y SEGUROS | P15: =+I15-O15 -> 0
B16: Conf. Art. 10 inc. e y f Ley N°941 | P16: =+I16-O16 -> 0
A17: 2 | B17: SERVICIOS PUBLICOS Y TASAS | I17: =++G20+G21+H18+G19 -> 335602.5 | J17: =+I17/$I$57 -> 0.060838257 | L17: 0 | M17: =+I17 -> 335602.5 | N17: 0 | O17: =SUM(L17:N17) -> 335602.5 | P17: =+I17-O17 -> 0
B18: EDESUR Medidor N° 073069158. Cliente N° 03271281. Débito 19/05 | G18: 0 | H18: 307018.96
B19: EDESUR cliente 163281 Débito 19/05 | G19: 1157.75 | H19: 0
B20: METROGAS Portería Cliente 10454407000 Medidor 4788767 7-02 al 10-03 Liq 2/2 | G20: 4784.68 | H20: 0
B21: METROGAS Cliente 10454393600 Medidor N° 31034348 7-02 al 10-03 Liq 2/2 | G21: 22641.11 | H21: 0
A23: 3 | B23: ABONOS DE SERVICIOS | I23: =SUM(G25:G25)+H24+G26+G28 -> 2194615.2 | J23: =+I23/$I$57 -> 0.39784138 | M23: =+H24+G25+G26+G28 -> 2194615.2 | N23: 0 | O23: =SUM(L23:N23) -> 2194615.2 | P23: =+I23-O23 -> 0
B24: LEFERTEK ASCENSORES SRL (30-71842952-4): abono ascensores 04/26 FC 329 | G24: 0 | H24: 159999.99 | Y24: 2504180.8
B25: GULLY (20-32919704-3): instalación térmica 04/26 FC 2566 | G25: 56000 | H25: 0
B26: SMART KLEANING (30-71561737-0): servicio de limpieza 04/26 FC 1395 | G26: 1889465.2 | H26: 0
B27: MAFRAP Desinf. urbanas SRL (30-64714402-7): serv. desinsectación abono sábado 04/26
B28: FC 180557 | G28: 89150 | H28: 0
P29: =+I29-O29 -> 0
A30: 4 | B30: MANTENIMIENTO DE PARTES COMUNES | I30: =SUM(G32:G36)+H32 -> 1877606.8 | J30: =+I30/$I$57 -> 0.34037388 | L30: =+G36 -> 13000 | M30: =+H32+G35 -> 1864606.8 | N30: 0 | O30: =SUM(L30:N30) -> 1877606.8
B31: LEFERTEK ASCENSORES SRL (30-71842952-4): cuota 1/2 por reemplazo de cables
B32: colgantes en ascensor de servicio s/Pto. FC 379 | G32: 0 | H32: 713406.8 | L32: HACER RECLASIF DE GASTO DE REP ASC 04/26
B33: MCH Conexiones (30-66148861-8): instalación de cámaras de seguridad, grabadora y acceso-
B34: rios de metal para resguardos de equipos y configuración a la red para la visualización en
B35: celulares FC 850. Saldo | G35: 1151200 | H35: 0
B36: ELECTROMEC (23-12801742-9): 10 bulboled 12w FC 993 | G36: 13000 | H36: 0
P37: =+I37-O37 -> 0
A38: 5 | B38: TRABAJOS DE REPARACIONES EN UNIDADES | I38: 0 | J38: =+I38/$I$57 -> 0 | L38: 0 | M38: 0 | O38: =SUM(L38:N38) -> 0 | P38: =+I38-O38 -> 0
L39: 0 | M39: =+I40 -> 174071.42 | N39: 0 | O39: =SUM(L39:N39) -> 174071.42 | P39: =+I40-O39 -> 0 | Q39: =811.1+170.33+4.87+1.02+10.46+60.14+6.83+4.59+200.59+42+223.5+308.57+128.4+197.52+220.19+36.96+338.7+210.73+18.55+0.71+28.54+40.35+62.07+6.83+52.79+81.21+52.36+80.54+22.38+6.43+43.55+43.55+15.48+74.24+5.88+41.52 -> 3653.48 | R39: =+M39 -> 174071.42 | S39: =+Q39-R39 -> -170417.94
A40: 6 | B40: GASTOS BANCARIOS | I40: =SUM(G41:G41) -> 174071.42 | J40: =+I40/$I$57 -> 0.031555789
B41: Gastos bancarios e imptos. cuenta corriente BANCO SANTANDER N° 558-000162/1 05/26 | G41: 174071.42 | H41: 0
L42: 0 | M42: 0 | N42: 0 | O42: =SUM(L42:N42) -> 0
A43: 7 | B43: GASTOS DE LIMPIEZA | I43: 0 | J43: =+I43/$I$57 -> 0
...

Sheet RES CUENTA
A2: ADMINISTRACION: | L2: CONSORCIO DE PROPIETARIOS:
A3: MARIANO CAUVIN | L3: =+LIQ!H3 -> MONTES DE OCA 1068/1070 C.A.B.A.
A4: AV.BELGRANO 1270 5°A C.A.B.A. | L4: =+LIQ!H4 -> CUIT: 30-66148861-8
A5: masoca_administraciones@hotmail.com | F5: 4381-0014 | L5: =+LIQ!H5 -> CLAVE SUTERH: 23883
A6: 20-16975070-0 | F6: Responsable Monotributo
A7: R.P.A. N° 470 | F7: URGENCIAS 155248-3729
A10: ESTADO DE CUENTAS Y PRORRATEO DE GASTOS AL 31/05/2026
A11: AVISO DE PAGO : FECHA DE VENCIMIENTO 10/06/2026
X13: Liquid | Y13: Cobranza Exp | AA13: Cobranza Cuota Ext
A14: U.F. | B14: DTO | C14: NOMBRE | D14: SALDO ANTERIOR | E14: SU PAGO | F14: % | G14: EXP. A | H14: % | J14: EXP. B | K14: OTROS | L14: TOTAL DEL MES | M14: DEUDA | N14: INTERE-SES | O14: OTROS | P14: TOTAL | Q14: FONDO | R14: OBSERVACIONES | S14: OBSERVAC | W14: U.F. | X14: S/ liquid | Y14: Banco Santander | Z14: Efvo | AA14: Banco | AB14: Efvo | AC14: Deuda | AD14: Mes | AE14: Subtotal | AF14: Interes del mes | AG14: Interes mes anterior | AH14: INT A 06/05 | AI14: Dif | AL14: SUP CUBIERTA | AM14: SUP TOTAL | AN14: SUP BAULERA | AO14: SUP GUARDACOCHE | AP14: TOTAL CUBIERTA | AQ14: % | AR14: % BAULERA | AX14: ROELA | AY14: RIO | AZ14: TOTAL
A15: 1 | B15: PB | C15: CAPRIA MARIA ESTHER | D15: =+X15 -> 569251.46 | E15: =-Y15-Z15 -> -569251 | F15: 10.52 | G15: =+$G$36*F15/100 -> 486428.99 | H15: 1.11 | I15: 0 | J15: =+$J$36*H15/100 -> 13102.726 | K15: 0 | L15: =+G15+J15+K15 -> 499531.72 | M15: 0 | N15: 0 | O15: 0 | P15: =+L15+M15+N15+O15 -> 499531.72 | Q15: 0 | S15: 210.6 | T15: 0 | U15: 26.51616 | V15: 0 | W15: 1 | X15: 569251.46 | Y15: 569251 | AC15: =+X15-Y15-Z15-AA15-AB15 -> 0.460158 | AD15: =+L15 -> 499531.72 | AE15: =+AC15+AD15 -> 499532.18 | AF15: =+P15-AE15 -> -0.460158 | AG15: 3418.0888 | AH15: =+N15 -> 0 | AI15: =+AG15-AH15 -> 3418.0888 | AJ15: =+AF15+AI15 -> 3417.6286 | AK15: cobrado | AL15: 304.69 | AM15: 304.69 | AQ15: 10.52 | AT15: =+F15 -> 10.52 | AY15: =+Y15 -> 569251 | AZ15: =+AX15+AY15 -> 569251 | BA15: =+Y15 -> 569251 | BB15: =+AZ15-BA15 -> 0
A16: =+A15+1 -> 2 | B16: 1 A | C16: DEGROSSI VICTORIO | D16: =+X16 -> 399441.07 | E16: =-Y16-Z16 -> -399441 | F16: 5.52 | G16: =+$G$36*F16/100 -> 255236.5 | H16: 6.169 | I16: =+F16/#REF!*100 -> #REF! | J16: =+$J$36*H16/100 -> 72820.465 | K16: 0 | L16: =+G16+J16+K16 -> 328056.97 | M16: 0 | N16: 0 | O16: 0 | P16: =+L16+M16+N16+O16 -> 328056.97 | Q16: 0 | S16: 127.725 | T16: 0 | U16: 16.08156 | V16: 0 | W16: =+W15+1 -> 2 | X16: 399441.07 | Z16: 399441 | AC16: =+X16-Y16-Z16-AA16-AB16 -> 0.0726674 | AD16: =+L16 -> 328056.97 | AE16: =+AC16+AD16 -> 328057.04 | AF16: =+P16-AE16 -> -0.0726674 | AG16: 0 | AH16: =+N16 -> 0 | AI16: =+AG16-AH16 -> 0 | AJ16: =+AF16+AI16 -> -0.0726674 | AL16: 125.7 | AM16: 146.93 | AN16: 1.74 | AP16: =+AM16+AN16 -> 148.67 | AQ16: 5.45 | AR16: 0.07 | AS16: =+AQ16+AR16 -> 5.52 | AT16: =+F16 -> 5.52 | AX16: 13034 | AZ16: =+AX16+AY16 -> 13034 | BA16: =+Y16 -> 0 | BB16: =+AZ16-BA16 -> 13034
A17: =+A16+1 -> 3 | B17: 1 B | C17: NIETO MANUEL | D17: =+X17 -> 305367 | E17: =-Y17-Z17 -> -305367 | F17: 4.22 | G17: =+$G$36*F17/100 -> 195126.46 | H17: 4.716 | I17: =+F17/#REF!*100 -> #REF! | J17: =+$J$36*H17/100 -> 55668.878 | K17: 0 | L17: =+G17+J17+K17 -> 250795.34 | M17: 0 | N17: 0 | O17: 0 | P17: =+L17+M17+N17+O17 -> 250795.34 | Q17: 0 | S17: 221.325 | T17: 20.814893 | U17: 27.86652 | V17: 22.184 | W17: =+W16+1 -> 3 | X17: 305367 | Y17: 305367 | AC17: =+X17-Y17-Z17-AA17-AB17 -> -0.0040424 | AD17: =+L17 -> 250795.34 | AE17: =+AC17+AD17 -> 250795.33 | AF17: =+P17-AE17 -> 0.0040424 | AG17: 0 | AH17: =+N17 -> 0 | AI17: =+AG17-AH17 -> 0 | AJ17: =+AF17+AI17 -> 0.0040424 | AL17: 98.03 | AM17: 119.92 | AN17: 1.78 | AP17: =+AM17+AN17 -> 121.7 | AQ17: 4.15 | AR17: 0.07 | AS17: =+AQ17+AR17 -> 4.22 | AT17: =+F17 -> 4.22 | AU17: Transferencia Recibida - De Aguilar, Marta Nora / 11042021 - Exp / 27054612805 | AX17: 9964 | AZ17: =+AX17+AY17 -> 9964 | BA17: =+Y17 -> 305367 | BB17: =+AZ17-BA17 -> -295403
A18: =+A17+1 -> 4 | B18: 2 A | C18: IRAOLA-RODRIGUEZ SORI | D18: =+X18 -> 399441.07 | E18: =-Y18-Z18 -> -400000 | F18: 5.52 | G18: =+$G$36*F18/100 -> 255236.5 | H18: 6.169 | I18: =+F18/#REF!*100 -> #REF! | J18: =+$J$36*H18/100 -> 72820.465 | K18: 0 | L18: =+G18+J18+K18 -> 328056.97 | M18: -559 | N18: 0 | O18: 0 | P18: =+L18+M18+N18+O18 -> 327497.97 | Q18: 0 | S18: 375.375 | T18: 35.191281 | U18: 47.2626 | V18: 37.506 | W18: =+W17+1 -> 4 | X18: 399441.07 | Y18: 400000 | AC18: =+X18-Y18-Z18-AA18-AB18 -> -558.92733 | AD18: =+L18 -> 328056.97 | AE18: =+AC18+AD18 -> 327498.04 | AF18: =+P18-AE18 -> -0.0726674 | AG18: 0 | AH18: =+N18 -> 0 | AI18: =+AG18-AH18 -> 0 | AJ18: =+AF18+AI18 -> -0.0726674 | AL18: 125.75 | AM18: 142.95 | AN18: 1.78 | AP18: =+AM18+AN18 -> 144.73 | AQ18: 5.45 | AR18: 0.07 | AS18: =+AQ18+AR18 -> 5.52 | AT18: =+F18 -> 5.52 | AX18: 13229.51 | AZ18: =+AX18+AY18 -> 13229.51 | BA18: =+Y18 -> 400000 | BB18: =+AZ18-BA18 -> -386770.49
A19: =+A18+1 -> 5 | B19: 2 B | C19: GOMEZ ANTONIO | D19: =+X19 -> 305303 | E19: =-Y19-Z19 -> -305303 | F19: 4.22 | G19: =+$G$36*F19/100 -> 195126.46 | H19: 4.716 | I19: =+F19/#REF!*100 -> #REF! | J19: =+$J$36*H19/100 -> 55668.878 | K19: 0 | L19: =+G19+J19+K19 -> 250795.34 | M19: 0 | N19: 0 | O19: 0 | P19: =+L19+M19+N19+O19 -> 250795.34 | Q19: 0 | S19: 177.45 | T19: 16.581356 | U19: 22.34232 | V19: 17.672 | W19: =+W18+1 -> 5 | X19: 305303 | Y19: 305303 | AC19: =+X19-Y19-Z19-AA19-AB19 -> -0.0040424 | AD19: =+L19 -> 250795.34 | AE19: =+AC19+AD19 -> 250795.33 | AF19: =+P19-AE19 -> 0.0040424 | AG19: 0 | AH19: =+N19 -> 0 | AI19: =+AG19-AH19 -> 0 | AJ19: =+AF19+AI19 -> 0.0040424 | AL19: 97.58 | AM19: 108.66 | AN19: 1.78 | AP19: =+AM19+AN19 -> 110.44 | AQ19: 4.15 | AR19: 0.07 | AS19: =+AQ19+AR19 -> 4.22 | AT19: =+F19 -> 4.22 | AU19: pouso | AX19: 9964 | AZ19: =+AX19+AY19 -> 9964 | BA19: =+Y19 -> 305303 | BB19: =+AZ19-BA19 -> -295339
A20: =+A19+1 -> 6 | B20: 3 A | C20: PECYNER GUILLERMO | D20: =+X20 -> 399441.07 | E20: =-Y20-Z20 -> -399441 | F20: 5.52 | G20: =+$G$36*F20/100 -> 255236.5 | H20: 6.169 | I20: =+F20/#REF!*100 -> #REF! | J20: =+$J$36*H20/100 -> 72820.465 | K20: 0 | L20: =+G20+J20+K20 -> 328056.97 | M20: 0 | N20: 0 | O20: 0 | P20: =+L20+M20+N20+O20 -> 328056.97 | Q20: 0 | S20: 267.15 | T20: 25.048431 | U20: 33.63624 | V20: 26.696 | W20: =+W19+1 -> 6 | X20: 399441.07 | Y20: 399441 | AC20: =+X20-Y20-Z20-AA20-AB20 -> 0.0726674 | AD20: =+L20 -> 328056.97 | AE20: =+AC20+AD20 -> 328057.04 | AF20: =+P20-AE20 -> -0.0726674 | AG20: 0 | AH20: =+N20 -> 0 | AI20: =+AG20-AH20 -> 0 | AJ20: =+AF20+AI20 -> -0.0726674 | AL20: 125.75 | AM20: 142.95 | AN20: 1.78 | AP20: =+AM20+AN20 -> 144.73 | AQ20: 5.45 | AR20: 0.07 | AS20: =+AQ20+AR20 -> 5.52 | AT20: =+F20 -> 5.52 | AY20: =+Y20 -> 399441 | AZ20: =+AX20+AY20 -> 399441 | BA20: =+Y20 -> 399441 | BB20: =+AZ20-BA20 -> 0
A21: =+A20+1 -> 7 | B21: 3 B | C21: ATAMANIUK ROMAN | D21: =+X21 -> 305367 | E21: =-Y21-Z21 -> -305367 | F21: =4.15+0.07 -> 4.22 | G21: =+$G$36*F21/100 -> 195126.46 | H21: 4.716 | I21: =+F21/#REF!*100 -> #REF! | J21: =+$J$36*H21/100 -> 55668.878 | K21: 0 | L21: =+G21+J21+K21 -> 250795.34 | M21: 0 | N21: 0 | O21: 0 | P21: =+L21+M21+N21+O21 -> 250795.34 | Q21: 0 | S21: 375.375 | T21: 35.191281 | U21: 47.2626 | V21: 37.506 | W21: =+W20+1 -> 7 | X21: 305367 | Y21: 305367 | AC21: =+X21-Y21-Z21-AA21-AB21 -> -0.0040423999 | AD21: =+L21 -> 250795.34 | AE21: =+AC21+AD21 -> 250795.33 | AF21: =+P21-AE21 -> 0.0040423999 | AG21: 0 | AH21: =+N21 -> 0 | AI21: =+AG21-AH21 -> 0 | AJ21: =+AF21+AI21 -> 0.0040423999 | AL21: 97.58 | AM21: 108.66 | AN21: 1.78 | AP21: =+AM21+AN21 -> 110.44 | AQ21: 4.15 | AR21: 0.07 | AS21: =+AQ21+AR21 -> 4.22 | AT21: =+F21 -> 4.22 | AU21: BRUNELLA | AY21: =+Y21 -> 305367 | AZ21: =+AX21+AY21 -> 305367 | BA21: =+Y21 -> 305367 | BB21: =+AZ21-BA21 -> 0 | BD21: Transferencia Recibida - De Messina/brunella / 3b - Exp / 27333140050
A22: =+A21+1 -> 8 | B22: 4 A | C22: LEINADO MIRTA ALCIRA Y OTROS | D22: =+X22 -> 399264.07 | E22: =-Y22-Z22 -> -399300 | F22: 5.52 | G22: =+$G$36*F22/100 -> 255236.5 | H22: 6.169 | I22: =+F22/#REF!*100 -> #REF! | J22: =+$J$36*H22/100 -> 72820.465 | K22: 0 | L22: =+G22+J22+K22 -> 328056.97 | M22: -36 | N22: 0 | O22: 0 | P22: =+L22+M22+N22+O22 -> 328020.97 | Q22: 0 | S22: 177.45 | T22: 16.581356 | U22: 22.34232 | V22: 17.672 | W22: =+W21+1 -> 8 | X22: 399264.07 | Y22: 399300 | AC22: =+X22-Y22-Z22-AA22-AB22 -> -35.927333 | AD22: =+L22 -> 328056.97 | AE22: =+AC22+AD22 -> 328021.04 | AF22: =+P22-AE22 -> -0.0726674 | AG22: 0 | AH22: =+N22 -> 0 | AI22: =+AG22-AH22 -> 0 | AJ22: =+AF22+AI22 -> -0.0726674 | AL22: 125.75 | AM22: 142.95 | AN22: 1.78 | AP22: =+AM22+AN22 -> 144.73 | AQ22: 5.45 | AR22: 0.07 | AS22: =+AQ22+AR22 -> 5.52 | AT22: =+F22 -> 5.52 | AX22: 13034 | AZ22: =+AX22+AY22 -> 13034 | BA22: =+Y22 -> 399300 | BB22: =+AZ22-BA22 -> -386266
A23: =+A22+1 -> 9 | B23: 4 B | C23: DELLA BELLA-BIDINOST | D23: =+X23 -> 305367 | E23: =-Y23-Z23 -> -305367 | F23: 4.22 | G23: =+$G$36*F23/100 -> 195126.46 | H23: 4.716 | I23: =+F23/#REF!*100 -> #REF! | J23: =+$J$36*H23/100 -> 55668.878 | K23: 0 | L23: =+G23+J23+K23 -> 250795.34 | M23: 0 | N23: 0 | O23: 0 | P23: =+L23+M23+N23+O23 -> 250795.34 | Q23: 0 | S23: 267.15 | T23: 25.048431 | U23: 33.63624 | V23: 26.696 | W23: =+W22+1 -> 9 | X23: 305367 | Y23: 305367 | AC23: =+X23-Y23-Z23-AA23-AB23 -> -0.0040424 | AD23: =+L23 -> 250795.34 | AE23: =+AC23+AD23 -> 250795.33 | AF23: =+P23-AE23 -> 0.0040424 | AG23: 0 | AH23: =+N23 -> 0 | AI23: =+AG23-AH23 -> 0 | AJ23: =+AF23+AI23 -> 0.0040424 | AL23: 97.58 | AM23: 108.66 | AN23: 1.78 | AP23: =+AM23+AN23 -> 110.44 | AQ23: 4.15 | AR23: 0.07 | AS23: =+AQ23+AR23 -> 4.22 | AT23: =+F23 -> 4.22 | AX23: 9964 | AZ23: =+AX23+AY23 -> 9964 | BA23: =+Y23 -> 305367 | BB23: =+AZ23-BA23 -> -295403
A24: =+A23+1 -> 10 | B24: 5 A | C24: AGOSTINI A- Y DI MARZO | D24: =+X24 -> 387667.21 | E24: =-Y24-Z24 -> -387667 | F24: 5.52 | G24: =+$G$36*F24/100 -> 255236.5 | H24: 5.52 | I24: =+F24/#REF!*100 -> #REF! | J24: =+$J$36*H24/100 -> 65159.501 | K24: 0 | L24: =+G24+J24+K24 -> 320396.01 | M24: 0 | N24: 0 | O24: 0 | P24: =+L24+M24+N24+O24 -> 320396.01 | Q24: 0 | S24: 375.375 | T24: 35.191281 | U24: 47.2626 | V24: 37.506 | W24: =+W23+1 -> 10 | X24: 387667.21 | Y24: 387667 | AC24: =+X24-Y24-Z24-AA24-AB24 -> 0.210064 | AD24: =+L24 -> 320396.01 | AE24: =+AC24+AD24 -> 320396.22 | AF24: =+P24-AE24 -> -0.210064 | AG24: 0 | AH24: =+N24 -> 0 | AI24: =+AG24-AH24 -> 0 | AJ24: =+AF24+AI24 -> -0.210064 | AL24: 125.75 | AM24: 142.95 | AN24: 1.78 | AP24: =+AM24+AN24 -> 144.73 | AQ24: 5.45 | AR24: 0.07 | AS24: =+AQ24+AR24 -> 5.52 | AT24: =+F24 -> 5.52 | AX24: 13121.92 | AZ24: =+AX24+AY24 -> 13121.92 | BA24: =+Y24 -> 387667 | BB24: =+AZ24-BA24 -> -374545.08
A25: =+A24+1 -> 11 | B25: 5 B | C25: LETTIERI PAULA | D25: =+X25 -> 308266.85 | E25: =-Y25-Z25 -> -308267 | F25: 4.26 | G25: =+$G$36*F25/100 -> 196976 | H25: 4.761 | I25: =+F25/#REF!*100 -> #REF! | J25: =+$J$36*H25/100 -> 56200.07 | K25: 0 | L25: =+G25+J25+K25 -> 253176.07 | M25: 0 | N25: 0 | O25: 0 | P25: =+L25+M25+N25+O25 -> 253176.07 | Q25: 0 | S25: 177.45 | T25: 16.581356 | U25: 22.34232 | V25: 17.672 | W25: =+W24+1 -> 11 | X25: 308266.85 | Y25: 308267 | AC25: =+X25-Y25-Z25-AA25-AB25 -> -0.1456814 | AD25: =+L25 -> 253176.07 | AE25: =+AC25+AD25 -> 253175.92 | AF25: =+P25-AE25 -> 0.1456814 | AG25: 0 | AH25: =+N25 -> 0 | AI25: =+AG25-AH25 -> 0 | AJ25: =+AF25+AI25 -> 0.1456814 | AL25: 97.58 | AM25: 108.66 | AN25: 2.7 | AP25: =+AM25+AN25 -> 111.36 | AQ25: 4.15 | AR25: 0.11 | AS25: =+AQ25+AR25 -> 4.26 | AT25: =+F25 -> 4.26 | AU25: Originante Gaggero/amanda O 27061516196 | AX25: 10059 | AZ25: =+AX25+AY25 -> 10059 | BA25: =+Y25 -> 308267 | BB25: =+AZ25-BA25 -> -298208
A26: =+A25+1 -> 12 | B26: 6 A | C26: RODRIGUEZ GERMAN | D26: =+X26 -> 399441.07 | E26: =-Y26-Z26 -> -399441 | F26: 5.52 | G26: =+$G$36*F26/100 -> 255236.5 | H26: 6.169 | I26: =+F26/#REF!*100 -> #REF! | J26: =+$J$36*H26/100 -> 72820.465 | K26: 0 | L26: =+G26+J26+K26 -> 328056.97 | M26: 0 | N26: 0 | O26: 0 | P26: =+L26+M26+N26+O26 -> 328056.97 | Q26: 0 | S26: 267.15 | T26: 25.048431 | U26: 33.63624 | V26: 26.696 | W26: =+W25+1 -> 12 | X26: 399441.07 | Y26: 399441 | AC26: =+X26-Y26-Z26-AA26-AB26 -> 0.0726674 | AD26: =+L26 -> 328056.97 | AE26: =+AC26+AD26 -> 328057.04 | AF26: =+P26-AE26 -> -0.0726674 | AG26: 0 | AH26: =+N26 -> 0 | AI26: =+AG26-AH26 -> 0 | AJ26: =+AF26+AI26 -> -0.0726674 | AL26: 125.75 | AM26: 142.95 | AN26: 1.78 | AP26: =+AM26+AN26 -> 144.73 | AQ26: 5.45 | AR26: 0.07 | AS26: =+AQ26+AR26 -> 5.52 | AT26: =+F26 -> 5.52 | AU26: Patricia C. ARgañaraz | AX26: 13034 | AZ26: =+AX26+AY26 -> 13034 | BA26: =+Y26 -> 399441 | BB26: =+AZ26-BA26 -> -386407 | BC26: Transferencia Recibida - De Menendez,maria Silvina / Expensas - Exp / 27310510675
A27: =+A26+1 -> 13 | B27: 6 B | C27: DEGROSSI HERNAN | D27: =+X27 -> 305098 | E27: =-Y27-Z27 -> -305559 | F27: 4.22 | G27: =+$G$36*F27/100 -> 195126.46 | H27: 4.716 | I27: =+F27/#REF!*100 -> #REF! | J27: =+$J$36*H27/100 -> 55668.878 | K27: 0 | L27: =+G27+J27+K27 -> 250795.34 | M27: -461 | N27: 0 | O27: 0 | P27: =+L27+M27+N27+O27 -> 250334.34 | Q27: 0 | S27: 375.375 | T27: 35.191281 | U27: 47.2626 | V27: 37.506 | W27: =+W26+1 -> 13 | X27: 305098 | Z27: =705000-399441 -> 305559 | AC27: =+X27-Y27-Z27-AA27-AB27 -> -461.00404 | AD27: =+L27 -> 250795.34 | AE27: =+AC27+AD27 -> 250334.33 | AF27: =+P27-AE27 -> 0.0040424 | AG27: 0 | AH27: =+N27 -> 0 | AI27: =+AG27-AH27 -> 0 | AJ27: =+AF27+AI27 -> 0.0040424 | AL27: 97.58 | AM27: 108.66 | AN27: 1.78 | AP27: =+AM27+AN27 -> 110.44 | AQ27: 4.15 | AR27: 0.07 | AS27: =+AQ27+AR27 -> 4.22 | AT27: =+F27 -> 4.22 | AX27: 10113.46 | AZ27: =+AX27+AY27 -> 10113.46 | BA27: =+Y27 -> 0 | BB27: =+AZ27-BA27 -> 10113.46
A28: =+A27+1 -> 14 | B28: 7 A | C28: FERNANDEZ MANUEL | D28: =+X28 -> 399441.07 | E28: =-Y28-Z28 -> -399441 | F28: 5.52 | G28: =+$G$36*F28/100 -> 255236.5 | H28: 6.169 | I28: =+F28/#REF!*100 -> #REF! | J28: =+$J$36*H28/100 -> 72820.465 | K28: 0 | L28: =+G28+J28+K28 -> 328056.97 | M28: 0 | N28: 0 | O28: 0 | P28: =+L28+M28+N28+O28 -> 328056.97 | Q28: 0 | S28: 177.45 | T28: 16.581356 | U28: 22.34232 | V28: 17.672 | W28: =+W27+1 -> 14 | X28: 399441.07 | Y28: =560806-161365 -> 399441 | AC28: =+X28-Y28-Z28-AA28-AB28 -> 0.0726674 | AD28: =+L28 -> 328056.97 | AE28: =+AC28+AD28 -> 328057.04 | AF28: =+P28-AE28 -> -0.0726674 | AG28: 0 | AH28: =+N28 -> 0 | AI28: =+AG28-AH28 -> 0 | AJ28: =+AF28+AI28 -> -0.0726674 | AL28: 125.75 | AM28: 142.95 | AN28: 1.78 | AO28: 89.76 | AP28: =+AM28+AN28 -> 144.73 | AQ28: 5.45 | AR28: 0.07 | AS28: =+AQ28+AR28 -> 5.52 | AT28: =+F28 -> 5.52 | AX28: 13034 | AZ28: =+AX28+AY28 -> 13034 | BA28: =+Y28 -> 399441 | BB28: =+AZ28-BA28 -> -386407
A29: =+A28+1 -> 15 | B29: 7 B | C29: ABOSSIO GONZALES MATIAS y OTRA (GONZALES PLATAS MARIANGELES) | D29: =+X29 -> 305367 | E29: =-Y29-Z29 -> -306000 | F29: 4.22 | G29: =+$G$36*F29/100 -> 195126.46 | H29: 4.716 | I29: =+F29/#REF!*100 -> #REF! | J29: =+$J$36*H29/100 -> 55668.878 | K29: 0 | L29: =+G29+J29+K29 -> 250795.34 | M29: -633 | N29: 0 | O29: 0 | P29: =+L29+M29+N29+O29 -> 250162.34 | Q29: 0 | S29: 267.15 | T29: 25.048431 | U29: 33.63624 | V29: 26.696 | W29: =+W28+1 -> 15 | X29: 305367 | Y29: 306000 | AC29: =+X29-Y29-Z29-AA29-AB29 -> -633.00404 | AD29: =+L29 -> 250795.34 | AE29: =+AC29+AD29 -> 250162.33 | AF29: =+P29-AE29 -> 0.0040424 | AG29: 0 | AH29: =+N29 -> 0 | AI29: =+AG29-AH29 -> 0 | AJ29: =+AF29+AI29 -> 0.0040424 | AL29: 97.58 | AM29: 108.66 | AN29: 1.78 | AP29: =+AM29+AN29 -> 110.44 | AQ29: 4.15 | AR29: 0.07 | AS29: =+AQ29+AR29 -> 4.22 | AT29: =+F29 -> 4.22 | AU29: Transferencia Recibida - De Calcagno Luis Enrique / - Var / 20276582454 | AX29: 9964 | AZ29: =+AX29+AY29 -> 9964 | BA29: =+Y29 -> 306000 | BB29: =+AZ29-BA29 -> -296036 | BD29: mbelach@hotmail.com
A30: =+A29+1 -> 16 | B30: 8 A | C30: KUZIW ANTONIO | D30: =+X30 -> 366126.82 | E30: =-Y30-Z30 -> -366000 | F30: 5.06 | G30: =+$G$36*F30/100 -> 233966.8 | H30: 5.655 | I30: =+F30/#REF!*100 -> #REF! | J30: =+$J$36*H30/100 -> 66753.076 | K30: 0 | L30: =+G30+J30+K30 -> 300719.87 | M30: =+INTERESES!F53 -> 127 | N30: =+INTERESES!I53 -> 3.81 | O30: 0 | P30: =+L30+M30+N30+O30 -> 300850.68 | Q30: 0 | S30: 375.375 | T30: 35.191281 | U30: 47.2626 | V30: 37.506 | W30: =+W29+1 -> 16 | X30: 366126.82 | Y30: 366000 | AC30: =+X30-Y30-Z30-AA30-AB30 -> 126.81942 | AD30: =+L30 -> 300719.87 | AE30: =+AC30+AD30 -> 300846.69 | AF30: =+P30-AE30 -> 3.990581 | AG30: 0 | AH30: =+N30 -> 3.81 | AI30: =+AG30-AH30 -> -3.81 | AJ30: =+AF30+AI30 -> 0.180581 | AL30: 125.75 | AM30: 142.95 | AN30: 1.82 | AP30: =+AM30+AN30 -> 144.77 | AQ30: 4.99 | AR30: 0.07 | AS30: =+AQ30+AR30 -> 5.06 | AT30: =+F30 -> 5.06 | AX30: 11948 | AZ30: =+AX30+AY30 -> 11948 | BA30: =+Y30 -> 366000 | BB30: =+AZ30-BA30 -> -354052
A31: =+A30+1 -> 17 | B31: 8 B | C31: SEIGNEUR ULISES | D31: =+X31 -> 275349.61 | E31: =-Y31-Z31 -> -275350 | F31: 3.92 | G31: =+$G$36*F31/100 -> 181254.91 | H31: 3.92 | I31: =+F31/#REF!*100 -> #REF! | J31: =+$J$36*H31/100 -> 46272.689 | K31: 0 | L31: =+G31+J31+K31 -> 227527.6 | M31: 0 | N31: 0 | O31: 0 | P31: =+L31+M31+N31+O31 -> 227527.6 | Q31: 0 | S31: 177.45 | T31: 16.581356 | U31: 22.34232 | V31: 17.672 | W31: =+W30+1 -> 17 | X31: 275349.61 | Y31: 275350 | AC31: =+X31-Y31-Z31-AA31-AB31 -> -0.387056 | AD31: =+L31 -> 227527.6 | AE31: =+AC31+AD31 -> 227527.21 | AF31: =+P31-AE31 -> 0.387056 | AG31: 0 | AH31: =+N31 -> 0 | AI31: =+AG31-AH31 -> 0 | AJ31: =+AF31+AI31 -> 0.387056 | AL31: 97.58 | AM31: 108.66 | AN31: 1.78 | AP31: =+AM31+AN31 -> 110.44 | AQ31: 3.85 | AR31: 0.07 | AS31: =+AQ31+AR31 -> 3.92 | AT31: =+F31 -> 3.92 | AX31: 9181 | AZ31: =+AX31+AY31 -> 9181 | BA31: =+Y31 -> 275350 | BB31: =+AZ31-BA31 -> -266169 | BD31: estefania peñalva
A32: =+A31+1 -> 18 | B32: 9 A | C32: VITA NORBERTO | D32: =+X32 -> 379898.59 | E32: =-Y32-Z32 -> -379899 | F32: 5.25 | G32: =+$G$36*F32/100 -> 242752.11 | H32: 5.867 | I32: =+F32/#REF!*100 -> #REF! | J32: =+$J$36*H32/100 -> 69255.579 | K32: 0 | L32: =+G32+J32+K32 -> 312007.69 | M32: 0 | N32: 0 | O32: 0 | P32: =+L32+M32+N32+O32 -> 312007.69 | Q32: 0 | S32: 267.15 | T32: 25.048431 | U32: 33.63624 | V32: 26.696 | W32: =+W31+1 -> 18 | X32: 379898.59 | Y32: 379899 | AC32: =+X32-Y32-Z32-AA32-AB32 -> -0.4123178 | AD32: =+L32 -> 312007.69 | AE32: =+AC32+AD32 -> 312007.28 | AF32: =+P32-AE32 -> 0.4123178 | AG32: 0 | AH32: =+N32 -> 0 | AI32: =+AG32-AH32 -> 0 | AJ32: =+AF32+AI32 -> 0.4123178 | AL32: 125.71 | AM32: 172.48 | AN32: 1.78 | AP32: =+AM32+AN32 -> 174.26 | AQ32: 5.18 | AR32: 0.07 | AS32: =+AQ32+AR32 -> 5.25 | AT32: =+F32 -> 5.25 | AX32: 12396 | AZ32: =+AX32+AY32 -> 12396 | BA32: =+Y32 -> 379899 | BB32: =+AZ32-BA32 -> -367503
A33: =+A32+1 -> 19 | B33: 9 B | C33: LOMBARDI EDUARDO | D33: =+X33 -> 140381.64 | E33: =-Y33-Z33 -> -140382 | F33: 1.94 | G33: =+$G$36*F33/100 -> 89702.685 | H33: 2.168 | I33: =+F33/#REF!*100 -> #REF! | J33: =+$J$36*H33/100 -> 25591.63 | K33: 0 | L33: =+G33+J33+K33 -> 115294.31 | M33: 0 | N33: 0 | O33: 0 | P33: =+L33+M33+N33+O33 -> 115294.31 | Q33: 0 | S33: 375.375 | T33: 35.191281 | U33: 47.2626 | V33: 37.506 | W33: =+W32+1 -> 19 | X33: 140381.64 | Y33: 140382 | AC33: =+X33-Y33-Z33-AA33-AB33 -> -0.3579472 | AD33: =+L33 -> 115294.31 | AE33: =+AC33+AD33 -> 115293.96 | AF33: =+P33-AE33 -> 0.3579472 | AG33: 0 | AH33: =+N33 -> 0 | AI33: =+AG33-AH33 -> 0 | AJ33: =+AF33+AI33 -> 0.3579472 | AL33: 47.1 | AM33: 57.15 | AN33: 1.78 | AP33: =+AM33+AN33 -> 58.93 | AQ33: 1.87 | AR33: 0.07 | AS33: =+AQ33+AR33 -> 1.94 | AT33: =+F33 -> 1.94 | AU33: barcelona | AV33: iraola | AX33: 4649.71 | AZ33: =+AX33+AY33 -> 4649.71 | BA33: =+Y33 -> 140382 | BB33: =+AZ33-BA33 -> -135732.29
A34: =+A33+1 -> 20 | B34: 10 A | C34: RAMIREZ PATRICIA G. D. | D34: =+X34 -> 206952.15 | E34: =-Y34-Z34 -> -206952 | F34: 2.86 | G34: =+$G$36*F34/100 -> 132242.1 | H34: 3.196 | I34: =+F34/#REF!*100 -> #REF! | J34: =+$J$36*H34/100 -> 37726.407 | K34: 0 | L34: =+G34+J34+K34 -> 169968.51 | M34: 0 | N34: 0 | O34: 0 | P34: =+L34+M34+N34+O34 -> 169968.51 | Q34: 0 | S34: 177.45 | T34: 16.581356 | U34: 22.34232 | V34: 17.672 | W34: =+W33+1 -> 20 | X34: 206952.15 | Y34: 206952 | AC34: =+X34-Y34-Z34-AA34-AB34 -> 0.1485496 | AD34: =+L34 -> 169968.51 | AE34: =+AC34+AD34 -> 169968.66 | AF34: =+P34-AE34 -> -0.1485496 | AG34: 0 | AH34: =+N34 -> 0 | AI34: =+AG34-AH34 -> 0 | AJ34: =+AF34+AI34 -> -0.1485496 | AL34: 63.38 | AM34: 110.26 | AN34: 1.78 | AP34: =+AM34+AN34 -> 112.04 | AQ34: 2.79 | AR34: 0.07 | AS34: =+AQ34+AR34 -> 2.86 | AT34: =+F34 -> 2.86 | AX34: 6753 | AZ34: =+AX34+AY34 -> 6753 | BA34: =+Y34 -> 206952 | BB34: =+AZ34-BA34 -> -200199
A35: =+A34+1 -> 21 | B35: C XX | C35: FERNANDEZ MANUEL | D35: =+X35 -> 161365.04 | E35: =-Y35-Z35 -> -161365 | F35: 2.23 | G35: =+$G$36*F35/100 -> 103111.85 | H35: 2.492 | I35: =+F35/#REF!*100 -> #REF! | J35: =+$J$36*H35/100 -> 29416.21 | K35: 0 | L35: =+G35+J35+K35 -> 132528.06 | M35: 0 | N35: 0 | O35: 0 | P35: =+L35+M35+N35+O35 -> 132528.06 | S35: 267.15 | T35: 25.048431 | U35: 33.63624 | V35: 26.696 | W35: =+W34+1 -> 21 | X35: 161365.04 | Y35: 161365 | AC35: =+X35-Y35-Z35-AA35-AB35 -> 0.0393752 | AD35: =+L35 -> 132528.06 | AE35: =+AC35+AD35 -> 132528.1 | AF35: =+P35-AE35 -> -0.0393752 | AG35: 0 | AH35: =+N35 -> 0 | AI35: =+AG35-AH35 -> 0 | AJ35: =+AF35+AI35 -> -0.0393752 | AL35: 0 | AM35: 0 | AN35: 0 | AO35: 89.76 | AP35: =+AO35 -> 89.76 | AQ35: 2.23 | AR35: 0 | AS35: =+AQ35+AR35 -> 2.23 | AT35: =+F35 -> 2.23 | AX35: 5266 | AZ35: =+AX35+AY35 -> 5266 | BA35: =+Y35 -> 161365 | BB35: =+AZ35-BA35 -> -156099
D36: =SUM(D15:D35) -> 7023597.8 | E36: =SUM(E15:E35) -> -7025160 | F36: =SUM(F15:F35) -> 100 | G36: =+LIQ!G63 -> 4623849.7 | H36: =SUM(H15:H35) -> 99.999 | I36: =SUM(I15:I35) -> #REF! | J36: =+LIQ!H63 -> 1180425.8 | K36: =SUM(K15:K35) -> 0 | L36: =SUM(L15:L35) -> 5804263.7 | M36: =SUM(M15:M35) -> -1562 | N36: =SUM(N15:N35) -> 3.81 | O36: =SUM(O15:O35) -> 0 | P36: =SUM(P15:P35) -> 5802705.5 | S36: 9750 | T36: 881.987 | U36: 1227.6 | V36: 940 | X36: 7023597.8 | Y36: =SUM(Y15:Y35) -> 6320160 | Z36: =SUM(Z15:Z35) -> 705000 | AA36: =SUM(AA15:AA35) -> 0 | AB36: =SUM(AB15:AB35) -> 0 | AC36: =SUM(AC15:AC35) -> -1562.2137 | AD36: =SUM(AD15:AD35) -> 5804263.7 | AE36: =SUM(AE15:AE35) -> 5802701.5 | AF36: =SUM(AF15:AF35) -> 4.0236866 | AG36: 3418.0888 | AH36: =SUM(AH15:AH35) -> 3.81 | AI36: =SUM(AI15:AI35) -> 3414.2788 | AJ36: =SUM(AJ15:AJ35) -> 3418.3025 | AP36: =SUM(AP16:AP35) -> 2492.51 | AX36: =SUM(AX15:AX35) -> 188709.6 | AY36: =SUM(AY15:AY35) -> 1274059 | AZ36: =+AX36+AY36 -> 1462768.6 | BA36: =+Y36 -> 6320160 | BB36: =+AZ36-BA36 -> -4857391.4
I37: s/acta N°7 18/06/1976 | V37: =27+27 -> 54 | AE37: AL 31/03 | AF37: AL 30/04 | AG37: AL 31/05 | BA37: =224201.44+16939+1285.16 -> 242425.6 | BB37: =+BB36+#REF! -> #REF! | BC37: 1285.16 | BD37: =+BB37-BC37 -> #REF!
A38: LAS EXPENSAS VENCEN EL DIA 10. PAGO FUERA DE TERMINO 3% DE INTERÉS MENSUAL | S38: =+G36 -> 4623849.7 | V38: =+'[3]RES CUENTA'!$F$50 -> 8125 | Y38: =+Y36+Z36-Y33-Z33 -> 6884778 | AE38: =+AD39+AD41+AD42-2000 -> -2000 | AF38: =+AD41+AD42-2000 -> -2000 | AG38: =+AD42 -> 0 | BA38: =+BA37-AX36-AY36 -> -1220343
A39: EN ´OTROS´SE CARGAN GASTOS PARTICULARES | I39: =+I31+I24-H24-H31 -> #REF! | Y39: 3504369
Y40: =+Y38-Y39 -> 3380409
A41: FORMAS DE PAGO: | S41: =+J36 -> 1180425.8 | V41: =+'[3]RES CUENTA'!$H$50 -> 940
A42: Depósito o transferencia:
A43: Titular: | D43: CONS AV MONTES DE OCA 1068
A44: Banco: | D44: SANTANDER | S44: =+K36 -> 0 | V44: =+'[3]RES CUENTA'!$J$50 -> 1988.0172
...

Sheet INTERESES
A1: =+'RES CUENTA'!A4 -> AV.BELGRANO 1270 5°A C.A.B.A.
A6: U.F. | B6: DTO | C6: NOMBRE | D6: 46054 | E6: 46082 | F6: 46113 | G6: TASA | H6: DIAS | I6: INTERES
A8: 1 | C8: =+'RES CUENTA'!C15 -> CAPRIA MARIA ESTHER
G9: 0.03 | J9: =+'RES CUENTA'!Y15 -> 569251 | L9: =+J9+K9 -> 569251
G10: 0.03 | H10: 30 | I10: =+#REF!*G10/30*H10 -> #REF!
A12: 2 | C12: =+'RES CUENTA'!C16 -> DEGROSSI VICTORIO | G12: 0.03 | H12: 30 | I12: =+#REF!*G12/30*H12 -> #REF!
A14: 3 | C14: =+'RES CUENTA'!C17 -> NIETO MANUEL | G14: 0.03 | H14: 30 | I14: =+#REF!*G14/30*H14 -> #REF!
A16: 4 | C16: =+'RES CUENTA'!C18 -> IRAOLA-RODRIGUEZ SORI | G16: 0.03 | H16: 30 | I16: =+D16*G16/30*H16 -> 0
A18: 5 | C18: =+'RES CUENTA'!C19 -> GOMEZ ANTONIO | G18: 0.02 | H18: 60 | I18: 0
G19: 0.02 | H19: 30 | I19: =+#REF!*G19/30*H19 -> #REF!
I20: =SUM(I18:I19) -> #REF!
A21: 6 | C21: =+'RES CUENTA'!C20 -> PECYNER GUILLERMO | G21: 0.02 | H21: 90
G22: 0.02 | H22: 60
G23: 0.02 | H23: 60
G24: 0.02 | H24: 30 | I24: =+#REF!*G24/30*H24 -> #REF!
I25: =SUM(I21:I24) -> #REF!
A26: 7 | C26: =+'RES CUENTA'!C21 -> ATAMANIUK ROMAN | H26: 90 | J26: =+'RES CUENTA'!Y21 -> 305367 | K26: -50 | L26: =+J26+K26 -> 305317
H27: 60 | L27: -1371
H28: 30 | L28: =+L26+L27 -> 303946
G29: 0.03 | H29: 30 | I29: =+#REF!*G29/30*H29 -> #REF!
I30: =SUM(I26:I29) -> #REF!
I31: =SUM(I26:I28) -> 0
A32: 8 | C32: =+'RES CUENTA'!C22 -> LEINADO MIRTA ALCIRA Y OTROS | G32: 0.02 | H32: 30 | I32: =+#REF!*G32/30*H32 -> #REF!
P33: =+'[4]RES CUENTA'!$K$23 -> 3775.4506 | Q33: =+N33+O33+P33 -> 3775.4506 | R33: -8000 | S33: -169
A34: 9 | C34: =+'RES CUENTA'!C23 -> DELLA BELLA-BIDINOST | G34: 0.02 | H34: 30 | I34: =+#REF!*G34/30*H34 -> #REF! | J34: =+'RES CUENTA'!Y23 -> 305367 | K34: =-'[5]RES CUENTA'!$M$23 -> -230.87084 | L34: =+J34+K34 -> 305136.13
G35: 0.02 | H35: 30 | I35: =+#REF!*G35/30*H35 -> #REF!
I36: =SUM(I34:I35) -> #REF! | L36: =+L34+#REF! -> #REF!
A38: 10 | C38: =+'RES CUENTA'!C24 -> AGOSTINI A- Y DI MARZO | F38: =+'[1]RES CUENTA'!$P$24 -> 387667.21 | G38: 0.03 | H38: 30 | I38: =+F38*G38/30*H38 -> 11630.016
A40: 11 | C40: =+'RES CUENTA'!C25 -> LETTIERI PAULA | G40: 0.02 | H40: 30 | I40: =+#REF!*G40/30*H40 -> #REF!
A42: 12 | C42: =+'RES CUENTA'!C26 -> RODRIGUEZ GERMAN | G42: 0.02 | H42: 60 | J42: =+'RES CUENTA'!Y26 -> 399441 | K42: =-'[6]RES CUENTA'!$M$26 -> -154.73407 | L42: =+J42+K42 -> 399286.27
G43: 0.03 | H43: 90
G44: 0.03 | H44: 60
G45: 0.03 | H45: 30 | I45: =+#REF!*G45/30*H45 -> #REF!
A47: 13 | C47: =+'RES CUENTA'!C27 -> DEGROSSI HERNAN | G47: 0.03 | H47: 30 | I47: =+#REF!*G47/30*H47 -> #REF!
A49: 14 | C49: =+'RES CUENTA'!C28 -> FERNANDEZ MANUEL | G49: 0.03 | H49: 30 | I49: =+#REF!*G49/30*H49 -> #REF!
A51: 15 | C51: =+'RES CUENTA'!C29 -> ABOSSIO GONZALES MATIAS y OTRA (GONZALES PLATAS MARIANGELES) | F51: =+'[1]RES CUENTA'!$L$29 -> 305367 | G51: 0.03 | H51: 30 | I51: =+F51*G51/30*H51 -> 9161.0099
A53: 16 | C53: =+'RES CUENTA'!C30 -> KUZIW ANTONIO | F53: 127 | G53: 0.03 | H53: 30 | I53: =+F53*G53/30*H53 -> 3.81
A55: 17 | C55: =+'RES CUENTA'!C31 -> SEIGNEUR ULISES | G55: 0.03 | H55: 60 | I55: 0
G56: 0.03 | H56: 30 | I56: =+#REF!*G56/30*H56 -> #REF!
I57: =SUM(I55:I56) -> #REF!
...

Sheet RECIBOS
C1: =+LIQ!J1 -> 46143 | E1: 46183 | F1: =+LIQ!H3 -> MONTES DE OCA 1068/1070 C.A.B.A.
C2: =+'RES CUENTA'!C15 -> CAPRIA MARIA ESTHER | D2: =+'RES CUENTA'!F15 -> 10.52 | E2: =+'RES CUENTA'!A15 -> 1 | F2: P/Depósito o transferencia en Banco Santander Rio | I2: =40*12 -> 480
C3: =+'RES CUENTA'!C16 -> DEGROSSI VICTORIO | D3: =+'RES CUENTA'!F16 -> 5.52 | E3: =+'RES CUENTA'!A16 -> 2 | F3: Cta. Cte. $ N° 558-000162/1
C4: =+'RES CUENTA'!C17 -> NIETO MANUEL | D4: =+'RES CUENTA'!F17 -> 4.22 | E4: =+'RES CUENTA'!A17 -> 3 | F4: CBU: 0720558320000000016218
C5: =+'RES CUENTA'!C18 -> IRAOLA-RODRIGUEZ SORI | D5: =+'RES CUENTA'!F18 -> 5.52 | E5: =+'RES CUENTA'!A18 -> 4 | F5: =+LIQ!H4 -> CUIT: 30-66148861-8
C6: =+'RES CUENTA'!C19 -> GOMEZ ANTONIO | D6: =+'RES CUENTA'!F19 -> 4.22 | E6: =+'RES CUENTA'!A19 -> 5
C7: =+'RES CUENTA'!C20 -> PECYNER GUILLERMO | D7: =+'RES CUENTA'!F20 -> 5.52 | E7: =+'RES CUENTA'!A20 -> 6
C8: =+'RES CUENTA'!C21 -> ATAMANIUK ROMAN | D8: =+'RES CUENTA'!F21 -> 4.22 | E8: =+'RES CUENTA'!A21 -> 7
C9: =+'RES CUENTA'!C22 -> LEINADO MIRTA ALCIRA Y OTROS | D9: =+'RES CUENTA'!F22 -> 5.52 | E9: =+'RES CUENTA'!A22 -> 8
C10: =+'RES CUENTA'!C23 -> DELLA BELLA-BIDINOST | D10: =+'RES CUENTA'!F23 -> 4.22 | E10: =+'RES CUENTA'!A23 -> 9
C11: =+'RES CUENTA'!C24 -> AGOSTINI A- Y DI MARZO | D11: =+'RES CUENTA'!F24 -> 5.52 | E11: =+'RES CUENTA'!A24 -> 10
C12: =+'RES CUENTA'!C25 -> LETTIERI PAULA | D12: =+'RES CUENTA'!F25 -> 4.26 | E12: =+'RES CUENTA'!A25 -> 11
C13: =+'RES CUENTA'!C26 -> RODRIGUEZ GERMAN | D13: =+'RES CUENTA'!F26 -> 5.52 | E13: =+'RES CUENTA'!A26 -> 12
C14: =+'RES CUENTA'!C27 -> DEGROSSI HERNAN | D14: =+'RES CUENTA'!F27 -> 4.22 | E14: =+'RES CUENTA'!A27 -> 13
C15: =+'RES CUENTA'!C28 -> FERNANDEZ MANUEL | D15: =+'RES CUENTA'!F28 -> 5.52 | E15: =+'RES CUENTA'!A28 -> 14
C16: =+'RES CUENTA'!C29 -> ABOSSIO GONZALES MATIAS y OTRA (GONZALES PLATAS MARIANGELES) | D16: =+'RES CUENTA'!F29 -> 4.22 | E16: =+'RES CUENTA'!A29 -> 15
C17: =+'RES CUENTA'!C30 -> KUZIW ANTONIO | D17: =+'RES CUENTA'!F30 -> 5.06 | E17: =+'RES CUENTA'!A30 -> 16
... C22: =+'RES CUENTA'!C35 -> FERNANDEZ MANUEL | D22: =+'RES CUENTA'!F35 -> 2.23 | E22: =+'RES CUENTA'!A35 -> 21
C23: =+'RES CUENTA'!#REF! -> #REF! | D23: =+'RES CUENTA'!#REF! -> #REF! | E23: =+'RES CUENTA'!#REF! -> #REF!
C24: =+'RES CUENTA'!#REF! -> #REF! | D24: =+'RES CUENTA'!#REF! -> #REF! | E24: =+'RES CUENTA'!#REF! -> #REF!
C25: =+'RES CUENTA'!#REF! -> #REF! | D25: =+'RES CUENTA'!#REF! -> #REF! | E25: =+'RES CUENTA'!#REF! -> #REF!
C26: =+'RES CUENTA'!#REF! -> #REF! | D26: =+'RES CUENTA'!#REF! -> #REF! | E26: =+'RES CUENTA'!#REF! -> #REF!
C27: =+'RES CUENTA'!#REF! -> #REF! | D27: =+'RES CUENTA'!#REF! -> #REF! | E27: =+'RES CUENTA'!#REF! -> #REF!
C28: =+'RES CUENTA'!#REF! -> #REF! | D28: =+'RES CUENTA'!#REF! -> #REF! | E28: =+'RES CUENTA'!#REF! -> #REF!
C29: =+'RES CUENTA'!#REF! -> #REF! | D29: =+'RES CUENTA'!#REF! -> #REF! | E29: =+'RES CUENTA'!#REF! -> #REF!
C30: =+'RES CUENTA'!#REF! -> #REF! | D30: =+'RES CUENTA'!#REF! -> #REF! | E30: =+'RES CUENTA'!#REF! -> #REF!
C31: =+'RES CUENTA'!#REF! -> #REF! | D31: =+'RES CUENTA'!#REF! -> #REF! | E31: =+'RES CUENTA'!#REF! -> #REF!
C32: =+'RES CUENTA'!#REF! -> #REF! | D32: =+'RES CUENTA'!#REF! -> #REF! | E32: =+'RES CUENTA'!#REF! -> #REF!
C33: =+'RES CUENTA'!#REF! -> #REF! | D33: =+'RES CUENTA'!#REF! -> #REF! | E33: =+'RES CUENTA'!#REF! -> #REF!
C34: =+'RES CUENTA'!#REF! -> #REF! | D34: =+'RES CUENTA'!#REF! -> #REF! | E34: =+'RES CUENTA'!#REF! -> #REF!
... C40: =+'RES CUENTA'!#REF! -> #REF! | D40: =+'RES CUENTA'!#REF! -> #REF! | E40: =+'RES CUENTA'!#REF! -> #REF!
F43: =+$C$1 -> 46143 | H43: =+$E$1 -> 46183
C47: =+C2 -> CAPRIA MARIA ESTHER | F47: MONTES DE OCA 1068/1070 C.A.B.A. | I47: Unid. 1
I48: =+'RES CUENTA'!B15 -> PB
C50: Expensas Gastos A | E50: =+'RES CUENTA'!G36 -> 4623849.7 | F50: =+'RES CUENTA'!F15 -> 10.52 | G50: =+E50*F50/100 -> 486428.99
C51: Expensas Gastos B | E51: =+'RES CUENTA'!J36 -> 1180425.8 | F51: =+'RES CUENTA'!H15 -> 1.11 | G51: =+E51*F51/100 -> 13102.726
C52: Otros | E52: 0 | F52: 0 | G52: =+'RES CUENTA'!K15 -> 0
C53: Deuda | E53: 0 | F53: 0 | G53: =+'RES CUENTA'!M15 -> 0
C54: Intereses | E54: 0 | F54: 0 | G54: =+'RES CUENTA'!N15 -> 0
G55: =SUM(G50:G54) -> 499531.72
...

Sheet SUELDO
A2: EMPLEADOR: CONS. DE PROP. BERUTI 4575/77 | F2: CUIT: 30-70807291-1
A3: Domicilio: Beruti 4575/77 | F3: Recibo: 1 ORIGINAL
B4: 1425 - Capital Federal | F4: Cuil: 23-11424220-9
A5: PERIODO | B5: APELLIDO Y NOMBRES | F5: Categoria | G5: Legajo
A6: 37653 | B6: OSUNA CLAUDIO R. | F6: 0-03 | G6: 1
A7: BANCO | B7: PERIODO DEPOSITADO | E7: FECHA | F7: TAREA | G7: INGRESO
A8: Nación | B8: Febrero 2003 | E8: 37687 | F8: Enc.Perm c/viv | G8: 37518
A9: CONCEPTOS | E9: UNIDADES | F9: REMUNERAC. | G9: DESCUENT.
A11: BASICO | F11: =374.4 -> 374.4 | I11: feriados,dom
A12: RETIRO DE RESIDUOS | E12: 15 | F12: =+E12*1.26 -> 18.9 | I12: 6
A13: PLUS JARDIN | F13: =16.98 -> 16.98 | I13: 5 | J13: DIAS
A14: PLUS COCHERA | F14: =16.98 -> 16.98 | I14: =+I12*I13 -> 30
A15: DEC.2641/02 | F15: 150 | I15: GRATIFICACION | O15: =+H17+109.74 -> 1832.43
A16: RET. JUBILACION | C16: 7 | D16: % | F16: - | G16: =#N/A -> #N/A | I16: DS NORMALES | K16: 1 | L16: =427.26/30*1 -> 14.242
A17: LEY N 19032 | C17: 3 | D17: % | F17: - | G17: =#N/A -> #N/A | H17: =895.36+727.33+100 -> 1722.69 | I17: HS EXTRAS | K17: 24 | L17: =427.26/200*2*24 -> 102.5424
A18: OBRA SOCIAL | C18: 2.7 | D18: % | F18: - | G18: =#N/A -> #N/A | L18: =+L16+L17 -> 116.7844
A19: ANSSAL | C19: 0.3 | D19: % | F19: - | G19: =#N/A -> #N/A | H19: =SUM(G16:G19) -> #N/A
A20: CUOTA SINDICAL | C20: 2 | D20: % | F20: - | G20: =#N/A -> #N/A | H20: =59.38+8.76+25.92+5.2+3.5+31.53 -> 134.29 | I20: SETIEMBRE
A21: CAJA PROT FAMILIA | C21: 1 | D21: % | F21: - | G21: =#N/A -> #N/A | H21: =134.29/583.86 -> 0.23000377 | I21: DS NORMALES | K21: 2.5 | L21: =427.26/30*2.5 -> 35.605
H22: =+H21*H17 -> 396.22519 | I22: HS EXTRAS | K22: 40 | L22: =427.26/200*2*40 -> 170.904
D23: TOTAL BRUTO | F23: =SUM(F11:F22) -> 577.26 | H23: =+H22+H19 -> #N/A
D24: TOTAL DESCUENTOS | F24: - | G24: =SUM(G16:G22) -> #N/A
D25: TOTAL NETO | F25: - | G25: =+F23-G24 -> #N/A
D26: REDONDEO | F26: - | G26: =ROUND(G25,0) -> #N/A
D27: SON PESOS:
A28: FIRMA DEL EMPLEADO | D28: SEICIENTOS OCHENTA Y OCHO
A29: Recibí de la firma cuyo rubro se indica arriba el importe neto de esta liquidación en pago de mi
A30: remuneración correspondiente al período indicado y duplicado de la misma.
A35: EMPLEADOR: CONS. DE PROP. BERUTI 4575/77 | F35: CUIT: 30-70807291-1
A36: Domicilio: Beruti 4575/77 | F36: Recibo: 2 DUPLICADO
B37: 1425 - Capital Federal | F37: Cuil: 23-11424220-9
A38: PERIODO | B38: APELLIDO Y NOMBRES | F38: Categoria | G38: Legajo
A39: =+A6 -> 37653 | B39: OSUNA CLAUDIO R. | F39: 0-03 | G39: 1
A40: BANCO | B40: PERIODO DEPOSITADO | E40: FECHA | F40: TAREA | G40: INGRESO
A41: Nación | B41: Febrero 2003 | E41: =+E8 -> 37687 | F41: Enc.Perm c/viv | G41: 37518
A42: CONCEPTOS | E42: UNIDADES | F42: REMUNERAC. | G42: DESCUENT.
A44: BASICO | F44: =374.4 -> 374.4
A45: HORAS EXTRAS 100% | E45: =3+3+8+3+8+3+8+3+8 -> 47 | F45: =+#REF! -> #REF!
A46: =+#REF! -> #REF! | E46: =+#REF! -> #REF! | F46: =+#REF! -> #REF!
A47: RETIRO DE RESIDUOS | E47: 15 | F47: =+E47*1.26 -> 18.9
...

Sheet Hoja3

Sheet Hoja4

Sheet Hoja2
A1: Local
A2: enero | B2: 2002 | C2: 593 | D2: 2950
A3: feb | C3: 720 | D3: 3589
A4: abrul | B4: 2002 | C4: 622 | D4: 3100
A6: mayo | C6: 697 | D6: 3472
A7: julio | B7: 2002 | C7: 677 | D7: 3379
A8: agost | C8: 689 | D8: 3430
A9: set | C9: 687 | D9: 3427
A10: dic | B10: 2002 | C10: 667 | D10: 3327
A11: enero | B11: 2003 | C11: 646 | D11: 3219
A12: feb | C12: 881 | D12: 4391
A13: marz | C13: 689 | D13: 3436
A14: abruil | C14: 680
A15: mayo | C15: 780

Sheet Hoja 3

Sheet Hoja1
A2: CONSORCIO SANTIAGO DEL ESTERO 338
A4: DETERMINACIÓN DE LAS COBRANZAS Y DE LOS SALDOS PENDIENTES DE COBRO AL 06/06/03
A7: Deuda anterior incluye intereses | E7: 60393.6
A8: Cobrado | E8: =-8052.31 -> -8052.31
A9: Deuda anterior (solamente capital) | E9: -50960.07
A10: Intereses pedientes de cobro correspondiente a deuda anterior | E10: =-'RES CUENTA'!#REF!+0.9 -> #REF!
A11: Importe incluido en Cobranzas y no en resumen de cuenta por no haber sido identificado | E11: 100
A12: Control | E12: =SUM(E7:E11) -> #REF!

Sheet Hoja5
